Workbook

Sheet RESULTS
A1: Sample | B1: Header= | C1: Peak | D1: RT | E1: First | F1: Max | G1: Last | H1: PK TY | I1: Height | J1: Area | K1: Pct Max | L1: Pct Total | M1: day
A2: 10-_-May-31-23 | B2: 1= | C2: 1 | D2: 4.275 | E2: 38 | F2: 59 | G2: 73 | H2: BV 5 | I2: 591995 | J2: 10547387 | K2: 0.72 | L2: 0.147 | M2: 1
A3: 10-_-May-31-23 | B3: 2= | C3: 2 | D3: 4.361 | E3: 73 | F3: 87 | G3: 153 | H3: PB | I3: 16880799 | J3: 367269522 | K3: 25.12 | L3: 5.131 | M3: 1
A4: 10-_-May-31-23 | B4: 3= | C4: 3 | D4: 5.427 | E4: 412 | F4: 424 | G4: 451 | H4: PV | I4: 6878808 | J4: 134868164 | K4: 9.22 | L4: 1.884 | M4: 1
A5: 10-_-May-31-23 | B5: 4= | C5: 4 | D5: 5.782 | E5: 507 | F5: 536 | G5: 554 | H5: VV | I5: 27828310 | J5: 830271702 | K5: 56.78 | L5: 11.599 | M5: 1
A6: 10-_-May-31-23 | B6: 5= | C6: 5 | D6: 5.86 | E6: 554 | F6: 561 | G6: 631 | H6: VV 2 | I6: 4663343 | J6: 287257859 | K6: 19.64 | L6: 4.013 | M6: 1
A7: 10-_-May-31-23 | B7: 6= | C7: 6 | D7: 6.116 | E7: 631 | F7: 642 | G7: 722 | H7: VB 7 | I7: 1215399 | J7: 67484218 | K7: 4.61 | L7: 0.943 | M7: 1
A8: 10-_-May-31-23 | B8: 7= | C8: 7 | D8: 6.722 | E8: 821 | F8: 833 | G8: 846 | H8: VV 4 | I8: 575222 | J8: 11847345 | K8: 0.81 | L8: 0.166 | M8: 1
A9: 10-_-May-31-23 | B9: 8= | C9: 8 | D9: 6.967 | E9: 883 | F9: 911 | G9: 927 | H9: BV 3 | I9: 951981 | J9: 20207509 | K9: 1.38 | L9: 0.282 | M9: 1
A10: 10-_-May-31-23 | B10: 9= | C10: 9 | D10: 7.091 | E10: 927 | F10: 950 | G10: 1024 | H10: VB 2 | I10: 1699954 | J10: 63676011 | K10: 4.35 | L10: 0.89 | M10: 1
A11: 10-_-May-31-23 | B11: 10= | C11: 10 | D11: 7.509 | E11: 1066 | F11: 1082 | G11: 1114 | H11: PB 5 | I11: 570043 | J11: 15813038 | K11: 1.08 | L11: 0.221 | M11: 1
A12: 10-_-May-31-23 | B12: 11= | C12: 11 | D12: 8.47 | E12: 1372 | F12: 1386 | G12: 1418 | H12: VB 4 | I12: 374819 | J12: 11813817 | K12: 0.81 | L12: 0.165 | M12: 1
A13: 10-_-May-31-23 | B13: 12= | C13: 12 | D13: 8.898 | E13: 1486 | F13: 1521 | G13: 1592 | H13: BB 4 | I13: 681336 | J13: 41888710 | K13: 2.86 | L13: 0.585 | M13: 1
... A3879: 774-F-Jun-06-23 | B3879: 106= | C3879: 106 | D3879: 32.872 | E3879: 9068 | F3879: 9103 | G3879: 9134 | H3879: BB 4 | I3879: 641148 | J3879: 17334170 | K3879: 0.08 | L3879: 0.032 | M3879: 2

Sheet proc
A1: sample | B1: mislabel.fix | C1: plant.id | D1: id.swa | E1: rt | F1: rt.round | G1: rt.final | H1: compound | I1: area | J1: standard.area | K1: wet.weight | L1: dry.weight | M1: swa | N1: type | O1: ngghr | P1: day | Q1: hours | R1: pair2
A2: 10-_-May-31-23 | B2: =IFERROR(VLOOKUP(A2,fix!$E:$F,2,FALSE),"") | C2: =VALUE(IF(B2="",LEFT(A2,FIND("-",A2)-1),B2)) -> 10 | D2: =C2&" ("&M2&")" -> 10 (0) | E2: 4.275 | F2: 4.28 | G2: =IFERROR(VLOOKUP(F2,'rt.comb'!$A:$B,2,FALSE),F2) -> 4.28 | H2: =IFERROR(VLOOKUP(G2,compounds!$A:$D,4,FALSE),"") | I2: 10547387 | J2: =SUMIFS($I:$I,$A:$A,A2,G:G,19.5) -> 46115552 | K2: =VLOOKUP($C2,rosie!$B$7:$D$38,2,FALSE) -> 4.9 | L2: =VLOOKUP(C2,rosie!$B$7:$F$66,5,FALSE) -> 1.14 | M2: =VLOOKUP($C2,rosie!$B$7:$D$38,3,FALSE) -> 0 | N2: =VLOOKUP($C2,rosie!$B$7:$E$38,4,FALSE) -> l | O2: =IFERROR((30/J2*I2)/K2/Q2,0) -> 0.70015251 | P2: =VLOOKUP(A2,RESULTS!$A:$M,13,FALSE) -> 1 | Q2: 2 | R2: =IF(VLOOKUP(C2,rosie!B:J,8,FALSE)=0,"x_x_x_x",VLOOKUP(C2,rosie!B:J,8,FALSE)) -> 3_5_31_2023
A3: 10-_-May-31-23 | B3: =IFERROR(VLOOKUP(A3,fix!$E:$F,2,FALSE),"") | C3: =VALUE(IF(B3="",LEFT(A3,FIND("-",A3)-1),B3)) -> 10 | D3: =C3&" ("&M3&")" -> 10 (0) | E3: 4.361 | F3: 4.36 | G3: =IFERROR(VLOOKUP(F3,'rt.comb'!$A:$B,2,FALSE),F3) -> 4.36 | H3: =IFERROR(VLOOKUP(G3,compounds!$A:$D,4,FALSE),"") | I3: 367269522 | J3: =SUMIFS($I:$I,$A:$A,A3,G:G,19.5) -> 46115552 | K3: =VLOOKUP($C3,rosie!$B$7:$D$38,2,FALSE) -> 4.9 | L3: =VLOOKUP(C3,rosie!$B$7:$F$66,5,FALSE) -> 1.14 | M3: =VLOOKUP($C3,rosie!$B$7:$D$38,3,FALSE) -> 0 | N3: =VLOOKUP($C3,rosie!$B$7:$E$38,4,FALSE) -> l | O3: =IFERROR((30/J3*I3)/K3/Q3,0) -> 24.379941 | P3: =VLOOKUP(A3,RESULTS!$A:$M,13,FALSE) -> 1 | Q3: 2 | R3: =IF(VLOOKUP(C3,rosie!B:J,8,FALSE)=0,"x_x_x_x",VLOOKUP(C3,rosie!B:J,8,FALSE)) -> 3_5_31_2023
A4: 10-_-May-31-23 | B4: =IFERROR(VLOOKUP(A4,fix!$E:$F,2,FALSE),"") | C4: =VALUE(IF(B4="",LEFT(A4,FIND("-",A4)-1),B4)) -> 10 | D4: =C4&" ("&M4&")" -> 10 (0) | E4: 5.427 | F4: 5.43 | G4: =IFERROR(VLOOKUP(F4,'rt.comb'!$A:$B,2,FALSE),F4) -> 5.43 | H4: =IFERROR(VLOOKUP(G4,compounds!$A:$D,4,FALSE),"") -> hydroxymethylpentanone | I4: 134868164 | J4: =SUMIFS($I:$I,$A:$A,A4,G:G,19.5) -> 46115552 | K4: =VLOOKUP($C4,rosie!$B$7:$D$38,2,FALSE) -> 4.9 | L4: =VLOOKUP(C4,rosie!$B$7:$F$66,5,FALSE) -> 1.14 | M4: =VLOOKUP($C4,rosie!$B$7:$D$38,3,FALSE) -> 0 | N4: =VLOOKUP($C4,rosie!$B$7:$E$38,4,FALSE) -> l | O4: =IFERROR((30/J4*I4)/K4/Q4,0) -> 8.9527656 | P4: =VLOOKUP(A4,RESULTS!$A:$M,13,FALSE) -> 1 | Q4: 2 | R4: =IF(VLOOKUP(C4,rosie!B:J,8,FALSE)=0,"x_x_x_x",VLOOKUP(C4,rosie!B:J,8,FALSE)) -> 3_5_31_2023
A5: 10-_-May-31-23 | B5: =IFERROR(VLOOKUP(A5,fix!$E:$F,2,FALSE),"") | C5: =VALUE(IF(B5="",LEFT(A5,FIND("-",A5)-1),B5)) -> 10 | D5: =C5&" ("&M5&")" -> 10 (0) | E5: 5.782 | F5: 5.78 | G5: =IFERROR(VLOOKUP(F5,'rt.comb'!$A:$B,2,FALSE),F5) -> 5.76 | H5: =IFERROR(VLOOKUP(G5,compounds!$A:$D,4,FALSE),"") -> zhexenol | I5: 830271702 | J5: =SUMIFS($I:$I,$A:$A,A5,G:G,19.5) -> 46115552 | K5: =VLOOKUP($C5,rosie!$B$7:$D$38,2,FALSE) -> 4.9 | L5: =VLOOKUP(C5,rosie!$B$7:$F$66,5,FALSE) -> 1.14 | M5: =VLOOKUP($C5,rosie!$B$7:$D$38,3,FALSE) -> 0 | N5: =VLOOKUP($C5,rosie!$B$7:$E$38,4,FALSE) -> l | O5: =IFERROR((30/J5*I5)/K5/Q5,0) -> 55.114771 | P5: =VLOOKUP(A5,RESULTS!$A:$M,13,FALSE) -> 1 | Q5: 2 | R5: =IF(VLOOKUP(C5,rosie!B:J,8,FALSE)=0,"x_x_x_x",VLOOKUP(C5,rosie!B:J,8,FALSE)) -> 3_5_31_2023
A6: 10-_-May-31-23 | B6: =IFERROR(VLOOKUP(A6,fix!$E:$F,2,FALSE),"") | C6: =VALUE(IF(B6="",LEFT(A6,FIND("-",A6)-1),B6)) -> 10 | D6: =C6&" ("&M6&")" -> 10 (0) | E6: 5.86 | F6: 5.86 | G6: =IFERROR(VLOOKUP(F6,'rt.comb'!$A:$B,2,FALSE),F6) -> 5.86 | H6: =IFERROR(VLOOKUP(G6,compounds!$A:$D,4,FALSE),"") | I6: 287257859 | J6: =SUMIFS($I:$I,$A:$A,A6,G:G,19.5) -> 46115552 | K6: =VLOOKUP($C6,rosie!$B$7:$D$38,2,FALSE) -> 4.9 | L6: =VLOOKUP(C6,rosie!$B$7:$F$66,5,FALSE) -> 1.14 | M6: =VLOOKUP($C6,rosie!$B$7:$D$38,3,FALSE) -> 0 | N6: =VLOOKUP($C6,rosie!$B$7:$E$38,4,FALSE) -> l | O6: =IFERROR((30/J6*I6)/K6/Q6,0) -> 19.068639 | P6: =VLOOKUP(A6,RESULTS!$A:$M,13,FALSE) -> 1 | Q6: 2 | R6: =IF(VLOOKUP(C6,rosie!B:J,8,FALSE)=0,"x_x_x_x",VLOOKUP(C6,rosie!B:J,8,FALSE)) -> 3_5_31_2023
A7: 10-_-May-31-23 | B7: =IFERROR(VLOOKUP(A7,fix!$E:$F,2,FALSE),"") | C7: =VALUE(IF(B7="",LEFT(A7,FIND("-",A7)-1),B7)) -> 10 | D7: =C7&" ("&M7&")" -> 10 (0) | E7: 6.116 | F7: 6.12 | G7: =IFERROR(VLOOKUP(F7,'rt.comb'!$A:$B,2,FALSE),F7) -> 6.11 | H7: =IFERROR(VLOOKUP(G7,compounds!$A:$D,4,FALSE),"") | I7: 67484218 | J7: =SUMIFS($I:$I,$A:$A,A7,G:G,19.5) -> 46115552 | K7: =VLOOKUP($C7,rosie!$B$7:$D$38,2,FALSE) -> 4.9 | L7: =VLOOKUP(C7,rosie!$B$7:$F$66,5,FALSE) -> 1.14 | M7: =VLOOKUP($C7,rosie!$B$7:$D$38,3,FALSE) -> 0 | N7: =VLOOKUP($C7,rosie!$B$7:$E$38,4,FALSE) -> l | O7: =IFERROR((30/J7*I7)/K7/Q7,0) -> 4.4797109 | P7: =VLOOKUP(A7,RESULTS!$A:$M,13,FALSE) -> 1 | Q7: 2 | R7: =IF(VLOOKUP(C7,rosie!B:J,8,FALSE)=0,"x_x_x_x",VLOOKUP(C7,rosie!B:J,8,FALSE)) -> 3_5_31_2023
A8: 10-_-May-31-23 | B8: =IFERROR(VLOOKUP(A8,fix!$E:$F,2,FALSE),"") | C8: =VALUE(IF(B8="",LEFT(A8,FIND("-",A8)-1),B8)) -> 10 | D8: =C8&" ("&M8&")" -> 10 (0) | E8: 6.722 | F8: 6.72 | G8: =IFERROR(VLOOKUP(F8,'rt.comb'!$A:$B,2,FALSE),F8) -> 6.72 | H8: =IFERROR(VLOOKUP(G8,compounds!$A:$D,4,FALSE),"") | I8: 11847345 | J8: =SUMIFS($I:$I,$A:$A,A8,G:G,19.5) -> 46115552 | K8: =VLOOKUP($C8,rosie!$B$7:$D$38,2,FALSE) -> 4.9 | L8: =VLOOKUP(C8,rosie!$B$7:$F$66,5,FALSE) -> 1.14 | M8: =VLOOKUP($C8,rosie!$B$7:$D$38,3,FALSE) -> 0 | N8: =VLOOKUP($C8,rosie!$B$7:$E$38,4,FALSE) -> l | O8: =IFERROR((30/J8*I8)/K8/Q8,0) -> 0.78644581 | P8: =VLOOKUP(A8,RESULTS!$A:$M,13,FALSE) -> 1 | Q8: 2 | R8: =IF(VLOOKUP(C8,rosie!B:J,8,FALSE)=0,"x_x_x_x",VLOOKUP(C8,rosie!B:J,8,FALSE)) -> 3_5_31_2023
A9: 10-_-May-31-23 | B9: =IFERROR(VLOOKUP(A9,fix!$E:$F,2,FALSE),"") | C9: =VALUE(IF(B9="",LEFT(A9,FIND("-",A9)-1),B9)) -> 10 | D9: =C9&" ("&M9&")" -> 10 (0) | E9: 6.967 | F9: 6.97 | G9: =IFERROR(VLOOKUP(F9,'rt.comb'!$A:$B,2,FALSE),F9) -> 6.97 | H9: =IFERROR(VLOOKUP(G9,compounds!$A:$D,4,FALSE),"") -> nonane | I9: 20207509 | J9: =SUMIFS($I:$I,$A:$A,A9,G:G,19.5) -> 46115552 | K9: =VLOOKUP($C9,rosie!$B$7:$D$38,2,FALSE) -> 4.9 | L9: =VLOOKUP(C9,rosie!$B$7:$F$66,5,FALSE) -> 1.14 | M9: =VLOOKUP($C9,rosie!$B$7:$D$38,3,FALSE) -> 0 | N9: =VLOOKUP($C9,rosie!$B$7:$E$38,4,FALSE) -> l | O9: =IFERROR((30/J9*I9)/K9/Q9,0) -> 1.3414069 | P9: =VLOOKUP(A9,RESULTS!$A:$M,13,FALSE) -> 1 | Q9: 2 | R9: =IF(VLOOKUP(C9,rosie!B:J,8,FALSE)=0,"x_x_x_x",VLOOKUP(C9,rosie!B:J,8,FALSE)) -> 3_5_31_2023
A10: 10-_-May-31-23 | B10: =IFERROR(VLOOKUP(A10,fix!$E:$F,2,FALSE),"") | C10: =VALUE(IF(B10="",LEFT(A10,FIND("-",A10)-1),B10)) -> 10 | D10: =C10&" ("&M10&")" -> 10 (0) | E10: 7.091 | F10: 7.09 | G10: =IFERROR(VLOOKUP(F10,'rt.comb'!$A:$B,2,FALSE),F10) -> 7.1 | H10: =IFERROR(VLOOKUP(G10,compounds!$A:$D,4,FALSE),"") -> heptanal | I10: 63676011 | J10: =SUMIFS($I:$I,$A:$A,A10,G:G,19.5) -> 46115552 | K10: =VLOOKUP($C10,rosie!$B$7:$D$38,2,FALSE) -> 4.9 | L10: =VLOOKUP(C10,rosie!$B$7:$F$66,5,FALSE) -> 1.14 | M10: =VLOOKUP($C10,rosie!$B$7:$D$38,3,FALSE) -> 0 | N10: =VLOOKUP($C10,rosie!$B$7:$E$38,4,FALSE) -> l | O10: =IFERROR((30/J10*I10)/K10/Q10,0) -> 4.226916 | P10: =VLOOKUP(A10,RESULTS!$A:$M,13,FALSE) -> 1 | Q10: 2 | R10: =IF(VLOOKUP(C10,rosie!B:J,8,FALSE)=0,"x_x_x_x",VLOOKUP(C10,rosie!B:J,8,FALSE)) -> 3_5_31_2023
A11: 10-_-May-31-23 | B11: =IFERROR(VLOOKUP(A11,fix!$E:$F,2,FALSE),"") | C11: =VALUE(IF(B11="",LEFT(A11,FIND("-",A11)-1),B11)) -> 10 | D11: =C11&" ("&M11&")" -> 10 (0) | E11: 7.509 | F11: 7.51 | G11: =IFERROR(VLOOKUP(F11,'rt.comb'!$A:$B,2,FALSE),F11) -> 7.51 | H11: =IFERROR(VLOOKUP(G11,compounds!$A:$D,4,FALSE),"") -> cyclopentane | I11: 15813038 | J11: =SUMIFS($I:$I,$A:$A,A11,G:G,19.5) -> 46115552 | K11: =VLOOKUP($C11,rosie!$B$7:$D$38,2,FALSE) -> 4.9 | L11: =VLOOKUP(C11,rosie!$B$7:$F$66,5,FALSE) -> 1.14 | M11: =VLOOKUP($C11,rosie!$B$7:$D$38,3,FALSE) -> 0 | N11: =VLOOKUP($C11,rosie!$B$7:$E$38,4,FALSE) -> l | O11: =IFERROR((30/J11*I11)/K11/Q11,0) -> 1.0496949 | P11: =VLOOKUP(A11,RESULTS!$A:$M,13,FALSE) -> 1 | Q11: 2 | R11: =IF(VLOOKUP(C11,rosie!B:J,8,FALSE)=0,"x_x_x_x",VLOOKUP(C11,rosie!B:J,8,FALSE)) -> 3_5_31_2023
A12: 10-_-May-31-23 | B12: =IFERROR(VLOOKUP(A12,fix!$E:$F,2,FALSE),"") | C12: =VALUE(IF(B12="",LEFT(A12,FIND("-",A12)-1),B12)) -> 10 | D12: =C12&" ("&M12&")" -> 10 (0) | E12: 8.47 | F12: 8.47 | G12: =IFERROR(VLOOKUP(F12,'rt.comb'!$A:$B,2,FALSE),F12) -> 8.47 | H12: =IFERROR(VLOOKUP(G12,compounds!$A:$D,4,FALSE),"") | I12: 11813817 | J12: =SUMIFS($I:$I,$A:$A,A12,G:G,19.5) -> 46115552 | K12: =VLOOKUP($C12,rosie!$B$7:$D$38,2,FALSE) -> 4.9 | L12: =VLOOKUP(C12,rosie!$B$7:$F$66,5,FALSE) -> 1.14 | M12: =VLOOKUP($C12,rosie!$B$7:$D$38,3,FALSE) -> 0 | N12: =VLOOKUP($C12,rosie!$B$7:$E$38,4,FALSE) -> l | O12: =IFERROR((30/J12*I12)/K12/Q12,0) -> 0.78422017 | P12: =VLOOKUP(A12,RESULTS!$A:$M,13,FALSE) -> 1 | Q12: 2 | R12: =IF(VLOOKUP(C12,rosie!B:J,8,FALSE)=0,"x_x_x_x",VLOOKUP(C12,rosie!B:J,8,FALSE)) -> 3_5_31_2023
A13: 10-_-May-31-23 | B13: =IFERROR(VLOOKUP(A13,fix!$E:$F,2,FALSE),"") | C13: =VALUE(IF(B13="",LEFT(A13,FIND("-",A13)-1),B13)) -> 10 | D13: =C13&" ("&M13&")" -> 10 (0) | E13: 8.898 | F13: 8.9 | G13: =IFERROR(VLOOKUP(F13,'rt.comb'!$A:$B,2,FALSE),F13) -> 8.92 | H13: =IFERROR(VLOOKUP(G13,compounds!$A:$D,4,FALSE),"") | I13: 41888710 | J13: =SUMIFS($I:$I,$A:$A,A13,G:G,19.5) -> 46115552 | K13: =VLOOKUP($C13,rosie!$B$7:$D$38,2,FALSE) -> 4.9 | L13: =VLOOKUP(C13,rosie!$B$7:$F$66,5,FALSE) -> 1.14 | M13: =VLOOKUP($C13,rosie!$B$7:$D$38,3,FALSE) -> 0 | N13: =VLOOKUP($C13,rosie!$B$7:$E$38,4,FALSE) -> l | O13: =IFERROR((30/J13*I13)/K13/Q13,0) -> 2.7806399 | P13: =VLOOKUP(A13,RESULTS!$A:$M,13,FALSE) -> 1 | Q13: 2 | R13: =IF(VLOOKUP(C13,rosie!B:J,8,FALSE)=0,"x_x_x_x",VLOOKUP(C13,rosie!B:J,8,FALSE)) -> 3_5_31_2023
... A250: 246-_-May-31-23 | B250: =IFERROR(VLOOKUP(A250,fix!$E:$F,2,FALSE),"") | C250: =VALUE(IF(B250="",LEFT(A250,FIND("-",A250)-1),B250)) -> 246 | D250: =C250&" ("&M250&")" -> 246 (1) | E250: 35.131 | F250: 35.13 | G250: =IFERROR(VLOOKUP(F250,'rt.comb'!$A:$B,2,FALSE),F250) -> 35.13 | H250: =IFERROR(VLOOKUP(G250,compounds!$A:$D,4,FALSE),"") | I250: 29175409 | J250: =SUMIFS($I:$I,$A:$A,A250,G:G,19.5) -> 30533038 | K250: =VLOOKUP($C250,rosie!$B$7:$D$38,2,FALSE) -> 8.21 | L250: =VLOOKUP(C250,rosie!$B$7:$F$66,5,FALSE) -> 1.48 | M250: =VLOOKUP($C250,rosie!$B$7:$D$38,3,FALSE) -> 1 | N250: =VLOOKUP($C250,rosie!$B$7:$E$38,4,FALSE) -> l | O250: =IFERROR((30/J250*I250)/K250/Q250,0) -> 1.7458022 | P250: =VLOOKUP(A250,RESULTS!$A:$M,13,FALSE) -> 1 | Q250: 2 | R250: =IF(VLOOKUP(C250,rosie!B:J,8,FALSE)=0,"x_x_x_x",VLOOKUP(C250,rosie!B:J,8,FALSE)) -> 4_5_31_2023
A251: 249-_-May-31-23 | B251: 247 | C251: =VALUE(IF(B251="",LEFT(A251,FIND("-",A251)-1),B251)) -> 247 | D251: =C251&" ("&M251&")" -> 247 (0) | E251: 4.276 | F251: 4.28 | G251: =IFERROR(VLOOKUP(F251,'rt.comb'!$A:$B,2,FALSE),F251) -> 4.28 | H251: =IFERROR(VLOOKUP(G251,compounds!$A:$D,4,FALSE),"") | I251: 16316492 | J251: =SUMIFS($I:$I,$A:$A,A251,G:G,19.5) -> 57141843 | K251: =VLOOKUP($C251,rosie!$B$7:$D$38,2,FALSE) -> 5.79 | L251: =VLOOKUP(C251,rosie!$B$7:$F$66,5,FALSE) -> 1.18 | M251: =VLOOKUP($C251,rosie!$B$7:$D$38,3,FALSE) -> 0 | N251: =VLOOKUP($C251,rosie!$B$7:$E$38,4,FALSE) -> l | O251: =IFERROR((30/J251*I251)/K251/Q251,0) -> 0.73975046 | P251: =VLOOKUP(A251,RESULTS!$A:$M,13,FALSE) -> 1 | Q251: 2 | R251: =IF(VLOOKUP(C251,rosie!B:J,8,FALSE)=0,"x_x_x_x",VLOOKUP(C251,rosie!B:J,8,FALSE)) -> 4_5_31_2023
A252: 249-_-May-31-23 | B252: 247 | C252: =VALUE(IF(B252="",LEFT(A252,FIND("-",A252)-1),B252)) -> 247 | D252: =C252&" ("&M252&")" -> 247 (0) | E252: 4.395 | F252: 4.4 | G252: =IFERROR(VLOOKUP(F252,'rt.comb'!$A:$B,2,FALSE),F252) -> 4.4 | H252: =IFERROR(VLOOKUP(G252,compounds!$A:$D,4,FALSE),"") | I252: 19645489 | J252: =SUMIFS($I:$I,$A:$A,A252,G:G,19.5) -> 57141843 | K252: =VLOOKUP($C252,rosie!$B$7:$D$38,2,FALSE) -> 5.79 | L252: =VLOOKUP(C252,rosie!$B$7:$F$66,5,FALSE) -> 1.18 | M252: =VLOOKUP($C252,rosie!$B$7:$D$38,3,FALSE) -> 0 | N252: =VLOOKUP($C252,rosie!$B$7:$E$38,4,FALSE) -> l | O252: =IFERROR((30/J252*I252)/K252/Q252,0) -> 0.89067917 | P252: =VLOOKUP(A252,RESULTS!$A:$M,13,FALSE) -> 1 | Q252: 2 | R252: =IF(VLOOKUP(C252,rosie!B:J,8,FALSE)=0,"x_x_x_x",VLOOKUP(C252,rosie!B:J,8,FALSE)) -> 4_5_31_2023
A253: 249-_-May-31-23 | B253: 247 | C253: =VALUE(IF(B253="",LEFT(A253,FIND("-",A253)-1),B253)) -> 247 | D253: =C253&" ("&M253&")" -> 247 (0) | E253: 4.636 | F253: 4.64 | G253: =IFERROR(VLOOKUP(F253,'rt.comb'!$A:$B,2,FALSE),F253) -> 4.64 | H253: =IFERROR(VLOOKUP(G253,compounds!$A:$D,4,FALSE),"") | I253: 6154850 | J253: =SUMIFS($I:$I,$A:$A,A253,G:G,19.5) -> 57141843 | K253: =VLOOKUP($C253,rosie!$B$7:$D$38,2,FALSE) -> 5.79 | L253: =VLOOKUP(C253,rosie!$B$7:$F$66,5,FALSE) -> 1.18 | M253: =VLOOKUP($C253,rosie!$B$7:$D$38,3,FALSE) -> 0 | N253: =VLOOKUP($C253,rosie!$B$7:$E$38,4,FALSE) -> l | O253: =IFERROR((30/J253*I253)/K253/Q253,0) -> 0.27904608 | P253: =VLOOKUP(A253,RESULTS!$A:$M,13,FALSE) -> 1 | Q253: 2 | R253: =IF(VLOOKUP(C253,rosie!B:J,8,FALSE)=0,"x_x_x_x",VLOOKUP(C253,rosie!B:J,8,FALSE)) -> 4_5_31_2023
A254: 249-_-May-31-23 | B254: 247 | C254: =VALUE(IF(B254="",LEFT(A254,FIND("-",A254)-1),B254)) -> 247 | D254: =C254&" ("&M254&")" -> 247 (0) | E254: 4.87 | F254: 4.87 | G254: =IFERROR(VLOOKUP(F254,'rt.comb'!$A:$B,2,FALSE),F254) -> 4.87 | H254: =IFERROR(VLOOKUP(G254,compounds!$A:$D,4,FALSE),"") | I254: 5280326 | J254: =SUMIFS($I:$I,$A:$A,A254,G:G,19.5) -> 57141843 | K254: =VLOOKUP($C254,rosie!$B$7:$D$38,2,FALSE) -> 5.79 | L254: =VLOOKUP(C254,rosie!$B$7:$F$66,5,FALSE) -> 1.18 | M254: =VLOOKUP($C254,rosie!$B$7:$D$38,3,FALSE) -> 0 | N254: =VLOOKUP($C254,rosie!$B$7:$E$38,4,FALSE) -> l | O254: =IFERROR((30/J254*I254)/K254/Q254,0) -> 0.23939727 | P254: =VLOOKUP(A254,RESULTS!$A:$M,13,FALSE) -> 1 | Q254: 2 | R254: =IF(VLOOKUP(C254,rosie!B:J,8,FALSE)=0,"x_x_x_x",VLOOKUP(C254,rosie!B:J,8,FALSE)) -> 4_5_31_2023
A255: 249-_-May-31-23 | B255: 247 | C255: =VALUE(IF(B255="",LEFT(A255,FIND("-",A255)-1),B255)) -> 247 | D255: =C255&" ("&M255&")" -> 247 (0) | E255: 5.427 | F255: 5.43 | G255: =IFERROR(VLOOKUP(F255,'rt.comb'!$A:$B,2,FALSE),F255) -> 5.43 | H255: =IFERROR(VLOOKUP(G255,compounds!$A:$D,4,FALSE),"") -> hydroxymethylpentanone | I255: 301930103 | J255: =SUMIFS($I:$I,$A:$A,A255,G:G,19.5) -> 57141843 | K255: =VLOOKUP($C255,rosie!$B$7:$D$38,2,FALSE) -> 5.79 | L255: =VLOOKUP(C255,rosie!$B$7:$F$66,5,FALSE) -> 1.18 | M255: =VLOOKUP($C255,rosie!$B$7:$D$38,3,FALSE) -> 0 | N255: =VLOOKUP($C255,rosie!$B$7:$E$38,4,FALSE) -> l | O255: =IFERROR((30/J255*I255)/K255/Q255,0) -> 13.688784 | P255: =VLOOKUP(A255,RESULTS!$A:$M,13,FALSE) -> 1 | Q255: 2 | R255: =IF(VLOOKUP(C255,rosie!B:J,8,FALSE)=0,"x_x_x_x",VLOOKUP(C255,rosie!B:J,8,FALSE)) -> 4_5_31_2023
A256: 249-_-May-31-23 | B256: 247 | C256: =VALUE(IF(B256="",LEFT(A256,FIND("-",A256)-1),B256)) -> 247 | D256: =C256&" ("&M256&")" -> 247 (0) | E256: 5.656 | F256: 5.66 | G256: =IFERROR(VLOOKUP(F256,'rt.comb'!$A:$B,2,FALSE),F256) -> 5.66 | H256: =IFERROR(VLOOKUP(G256,compounds!$A:$D,4,FALSE),"") | I256: 10401972 | J256: =SUMIFS($I:$I,$A:$A,A256,G:G,19.5) -> 57141843 | K256: =VLOOKUP($C256,rosie!$B$7:$D$38,2,FALSE) -> 5.79 | L256: =VLOOKUP(C256,rosie!$B$7:$F$66,5,FALSE) -> 1.18 | M256: =VLOOKUP($C256,rosie!$B$7:$D$38,3,FALSE) -> 0 | N256: =VLOOKUP($C256,rosie!$B$7:$E$38,4,FALSE) -> l | O256: =IFERROR((30/J256*I256)/K256/Q256,0) -> 0.47160036 | P256: =VLOOKUP(A256,RESULTS!$A:$M,13,FALSE) -> 1 | Q256: 2 | R256: =IF(VLOOKUP(C256,rosie!B:J,8,FALSE)=0,"x_x_x_x",VLOOKUP(C256,rosie!B:J,8,FALSE)) -> 4_5_31_2023
A257: 249-_-May-31-23 | B257: 247 | C257: =VALUE(IF(B257="",LEFT(A257,FIND("-",A257)-1),B257)) -> 247 | D257: =C257&" ("&M257&")" -> 247 (0) | E257: 5.771 | F257: 5.77 | G257: =IFERROR(VLOOKUP(F257,'rt.comb'!$A:$B,2,FALSE),F257) -> 5.76 | H257: =IFERROR(VLOOKUP(G257,compounds!$A:$D,4,FALSE),"") -> zhexenol | I257: 591758040 | J257: =SUMIFS($I:$I,$A:$A,A257,G:G,19.5) -> 57141843 | K257: =VLOOKUP($C257,rosie!$B$7:$D$38,2,FALSE) -> 5.79 | L257: =VLOOKUP(C257,rosie!$B$7:$F$66,5,FALSE) -> 1.18 | M257: =VLOOKUP($C257,rosie!$B$7:$D$38,3,FALSE) -> 0 | N257: =VLOOKUP($C257,rosie!$B$7:$E$38,4,FALSE) -> l | O257: =IFERROR((30/J257*I257)/K257/Q257,0) -> 26.828885 | P257: =VLOOKUP(A257,RESULTS!$A:$M,13,FALSE) -> 1 | Q257: 2 | R257: =IF(VLOOKUP(C257,rosie!B:J,8,FALSE)=0,"x_x_x_x",VLOOKUP(C257,rosie!B:J,8,FALSE)) -> 4_5_31_2023
A258: 249-_-May-31-23 | B258: 247 | C258: =VALUE(IF(B258="",LEFT(A258,FIND("-",A258)-1),B258)) -> 247 | D258: =C258&" ("&M258&")" -> 247 (0) | E258: 5.869 | F258: 5.87 | G258: =IFERROR(VLOOKUP(F258,'rt.comb'!$A:$B,2,FALSE),F258) -> 5.87 | H258: =IFERROR(VLOOKUP(G258,compounds!$A:$D,4,FALSE),"") | I258: 122246862 | J258: =SUMIFS($I:$I,$A:$A,A258,G:G,19.5) -> 57141843 | K258: =VLOOKUP($C258,rosie!$B$7:$D$38,2,FALSE) -> 5.79 | L258: =VLOOKUP(C258,rosie!$B$7:$F$66,5,FALSE) -> 1.18 | M258: =VLOOKUP($C258,rosie!$B$7:$D$38,3,FALSE) -> 0 | N258: =VLOOKUP($C258,rosie!$B$7:$E$38,4,FALSE) -> l | O258: =IFERROR((30/J258*I258)/K258/Q258,0) -> 5.5423784 | P258: =VLOOKUP(A258,RESULTS!$A:$M,13,FALSE) -> 1 | Q258: 2 | R258: =IF(VLOOKUP(C258,rosie!B:J,8,FALSE)=0,"x_x_x_x",VLOOKUP(C258,rosie!B:J,8,FALSE)) -> 4_5_31_2023
A259: 249-_-May-31-23 | B259: 247 | C259: =VALUE(IF(B259="",LEFT(A259,FIND("-",A259)-1),B259)) -> 247 | D259: =C259&" ("&M259&")" -> 247 (0) | E259: 6.113 | F259: 6.11 | G259: =IFERROR(VLOOKUP(F259,'rt.comb'!$A:$B,2,FALSE),F259) -> 6.11 | H259: =IFERROR(VLOOKUP(G259,compounds!$A:$D,4,FALSE),"") | I259: 41037581 | J259: =SUMIFS($I:$I,$A:$A,A259,G:G,19.5) -> 57141843 | K259: =VLOOKUP($C259,rosie!$B$7:$D$38,2,FALSE) -> 5.79 | L259: =VLOOKUP(C259,rosie!$B$7:$F$66,5,FALSE) -> 1.18 | M259: =VLOOKUP($C259,rosie!$B$7:$D$38,3,FALSE) -> 0 | N259: =VLOOKUP($C259,rosie!$B$7:$E$38,4,FALSE) -> l | O259: =IFERROR((30/J259*I259)/K259/Q259,0) -> 1.8605451 | P259: =VLOOKUP(A259,RESULTS!$A:$M,13,FALSE) -> 1 | Q259: 2 | R259: =IF(VLOOKUP(C259,rosie!B:J,8,FALSE)=0,"x_x_x_x",VLOOKUP(C259,rosie!B:J,8,FALSE)) -> 4_5_31_2023
A260: 249-_-May-31-23 | B260: 247 | C260: =VALUE(IF(B260="",LEFT(A260,FIND("-",A260)-1),B260)) -> 247 | D260: =C260&" ("&M260&")" -> 247 (0) | E260: 6.722 | F260: 6.72 | G260: =IFERROR(VLOOKUP(F260,'rt.comb'!$A:$B,2,FALSE),F260) -> 6.72 | H260: =IFERROR(VLOOKUP(G260,compounds!$A:$D,4,FALSE),"") | I260: 13674541 | J260: =SUMIFS($I:$I,$A:$A,A260,G:G,19.5) -> 57141843 | K260: =VLOOKUP($C260,rosie!$B$7:$D$38,2,FALSE) -> 5.79 | L260: =VLOOKUP(C260,rosie!$B$7:$F$66,5,FALSE) -> 1.18 | M260: =VLOOKUP($C260,rosie!$B$7:$D$38,3,FALSE) -> 0 | N260: =VLOOKUP($C260,rosie!$B$7:$E$38,4,FALSE) -> l | O260: =IFERROR((30/J260*I260)/K260/Q260,0) -> 0.61997076 | P260: =VLOOKUP(A260,RESULTS!$A:$M,13,FALSE) -> 1 | Q260: 2 | R260: =IF(VLOOKUP(C260,rosie!B:J,8,FALSE)=0,"x_x_x_x",VLOOKUP(C260,rosie!B:J,8,FALSE)) -> 4_5_31_2023
A261: 249-_-May-31-23 | B261: 247 | C261: =VALUE(IF(B261="",LEFT(A261,FIND("-",A261)-1),B261)) -> 247 | D261: =C261&" ("&M261&")" -> 247 (0) | E261: 6.968 | F261: 6.97 | G261: =IFERROR(VLOOKUP(F261,'rt.comb'!$A:$B,2,FALSE),F261) -> 6.97 | H261: =IFERROR(VLOOKUP(G261,compounds!$A:$D,4,FALSE),"") -> nonane | I261: 18728093 | J261: =SUMIFS($I:$I,$A:$A,A261,G:G,19.5) -> 57141843 | K261: =VLOOKUP($C261,rosie!$B$7:$D$38,2,FALSE) -> 5.79 | L261: =VLOOKUP(C261,rosie!$B$7:$F$66,5,FALSE) -> 1.18 | M261: =VLOOKUP($C261,rosie!$B$7:$D$38,3,FALSE) -> 0 | N261: =VLOOKUP($C261,rosie!$B$7:$E$38,4,FALSE) -> l | O261: =IFERROR((30/J261*I261)/K261/Q261,0) -> 0.84908664 | P261: =VLOOKUP(A261,RESULTS!$A:$M,13,FALSE) -> 1 | Q261: 2 | R261: =IF(VLOOKUP(C261,rosie!B:J,8,FALSE)=0,"x_x_x_x",VLOOKUP(C261,rosie!B:J,8,FALSE)) -> 4_5_31_2023
A262: 249-_-May-31-23 | B262: 247 | C262: =VALUE(IF(B262="",LEFT(A262,FIND("-",A262)-1),B262)) -> 247 | D262: =C262&" ("&M262&")" -> 247 (0) | E262: 7.094 | F262: 7.09 | G262: =IFERROR(VLOOKUP(F262,'rt.comb'!$A:$B,2,FALSE),F262) -> 7.1 | H262: =IFERROR(VLOOKUP(G262,compounds!$A:$D,4,FALSE),"") -> heptanal | I262: 17470397 | J262: =SUMIFS($I:$I,$A:$A,A262,G:G,19.5) -> 57141843 | K262: =VLOOKUP($C262,rosie!$B$7:$D$38,2,FALSE) -> 5.79 | L262: =VLOOKUP(C262,rosie!$B$7:$F$66,5,FALSE) -> 1.18 | M262: =VLOOKUP($C262,rosie!$B$7:$D$38,3,FALSE) -> 0 | N262: =VLOOKUP($C262,rosie!$B$7:$E$38,4,FALSE) -> l | O262: =IFERROR((30/J262*I262)/K262/Q262,0) -> 0.79206573 | P262: =VLOOKUP(A262,RESULTS!$A:$M,13,FALSE) -> 1 | Q262: 2 | R262: =IF(VLOOKUP(C262,rosie!B:J,8,FALSE)=0,"x_x_x_x",VLOOKUP(C262,rosie!B:J,8,FALSE)) -> 4_5_31_2023
... A337: 249-_-May-31-23 | B337: 247 | C337: =VALUE(IF(B337="",LEFT(A337,FIND("-",A337)-1),B337)) -> 247 | D337: =C337&" ("&M337&")" -> 247 (0) | E337: 39.81 | F337: 39.81 | G337: =IFERROR(VLOOKUP(F337,'rt.comb'!$A:$B,2,FALSE),F337) -> 39.81 | H337: =IFERROR(VLOOKUP(G337,compounds!$A:$D,4,FALSE),"") | I337: 6978818 | J337: =SUMIFS($I:$I,$A:$A,A337,G:G,19.5) -> 57141843 | K337: =VLOOKUP($C337,rosie!$B$7:$D$38,2,FALSE) -> 5.79 | L337: =VLOOKUP(C337,rosie!$B$7:$F$66,5,FALSE) -> 1.18 | M337: =VLOOKUP($C337,rosie!$B$7:$D$38,3,FALSE) -> 0 | N337: =VLOOKUP($C337,rosie!$B$7:$E$38,4,FALSE) -> l | O337: =IFERROR((30/J337*I337)/K337/Q337,0) -> 0.3164028 | P337: =VLOOKUP(A337,RESULTS!$A:$M,13,FALSE) -> 1 | Q337: 2 | R337: =IF(VLOOKUP(C337,rosie!B:J,8,FALSE)=0,"x_x_x_x",VLOOKUP(C337,rosie!B:J,8,FALSE)) -> 4_5_31_2023
A338: 394-_-May-31-23 | C338: =VALUE(IF(B338="",LEFT(A338,FIND("-",A338)-1),B338)) -> 394 | D338: =C338&" ("&M338&")" -> 394 (1) | E338: 4.279 | F338: 4.28 | G338: =IFERROR(VLOOKUP(F338,'rt.comb'!$A:$B,2,FALSE),F338) -> 4.28 | H338: =IFERROR(VLOOKUP(G338,compounds!$A:$D,4,FALSE),"") | I338: 15547488 | J338: =SUMIFS($I:$I,$A:$A,A338,G:G,19.5) -> 36699569 | K338: =VLOOKUP($C338,rosie!$B$7:$D$38,2,FALSE) -> 5.62 | L338: =VLOOKUP(C338,rosie!$B$7:$F$66,5,FALSE) -> 1.19 | M338: =VLOOKUP($C338,rosie!$B$7:$D$38,3,FALSE) -> 1 | N338: =VLOOKUP($C338,rosie!$B$7:$E$38,4,FALSE) -> l | O338: =IFERROR((30/J338*I338)/K338/Q338,0) -> 1.1307178 | P338: =VLOOKUP(A338,RESULTS!$A:$M,13,FALSE) -> 1 | Q338: 2 | R338: =IF(VLOOKUP(C338,rosie!B:J,8,FALSE)=0,"x_x_x_x",VLOOKUP(C338,rosie!B:J,8,FALSE)) -> 5_5_31_2023
A339: 394-_-May-31-23 | C339: =VALUE(IF(B339="",LEFT(A339,FIND("-",A339)-1),B339)) -> 394 | D339: =C339&" ("&M339&")" -> 394 (1) | E339: 4.364 | F339: 4.36 | G339: =IFERROR(VLOOKUP(F339,'rt.comb'!$A:$B,2,FALSE),F339) -> 4.36 | H339: =IFERROR(VLOOKUP(G339,compounds!$A:$D,4,FALSE),"") | I339: 233323115 | J339: =SUMIFS($I:$I,$A:$A,A339,G:G,19.5) -> 36699569 | K339: =VLOOKUP($C339,rosie!$B$7:$D$38,2,FALSE) -> 5.62 | L339: =VLOOKUP(C339,rosie!$B$7:$F$66,5,FALSE) -> 1.19 | M339: =VLOOKUP($C339,rosie!$B$7:$D$38,3,FALSE) -> 1 | N339: =VLOOKUP($C339,rosie!$B$7:$E$38,4,FALSE) -> l | O339: =IFERROR((30/J339*I339)/K339/Q339,0) -> 16.968824 | P339: =VLOOKUP(A339,RESULTS!$A:$M,13,FALSE) -> 1 | Q339: 2 | R339: =IF(VLOOKUP(C339,rosie!B:J,8,FALSE)=0,"x_x_x_x",VLOOKUP(C339,rosie!B:J,8,FALSE)) -> 5_5_31_2023
A340: 394-_-May-31-23 | C340: =VALUE(IF(B340="",LEFT(A340,FIND("-",A340)-1),B340)) -> 394 | D340: =C340&" ("&M340&")" -> 394 (1) | E340: 4.876 | F340: 4.88 | G340: =IFERROR(VLOOKUP(F340,'rt.comb'!$A:$B,2,FALSE),F340) -> 4.88 | H340: =IFERROR(VLOOKUP(G340,compounds!$A:$D,4,FALSE),"") | I340: 32304449 | J340: =SUMIFS($I:$I,$A:$A,A340,G:G,19.5) -> 36699569 | K340: =VLOOKUP($C340,rosie!$B$7:$D$38,2,FALSE) -> 5.62 | L340: =VLOOKUP(C340,rosie!$B$7:$F$66,5,FALSE) -> 1.19 | M340: =VLOOKUP($C340,rosie!$B$7:$D$38,3,FALSE) -> 1 | N340: =VLOOKUP($C340,rosie!$B$7:$E$38,4,FALSE) -> l | O340: =IFERROR((30/J340*I340)/K340/Q340,0) -> 2.3493965 | P340: =VLOOKUP(A340,RESULTS!$A:$M,13,FALSE) -> 1 | Q340: 2 | R340: =IF(VLOOKUP(C340,rosie!B:J,8,FALSE)=0,"x_x_x_x",VLOOKUP(C340,rosie!B:J,8,FALSE)) -> 5_5_31_2023
A341: 394-_-May-31-23 | C341: =VALUE(IF(B341="",LEFT(A341,FIND("-",A341)-1),B341)) -> 394 | D341: =C341&" ("&M341&")" -> 394 (1) | E341: 5.457 | F341: 5.46 | G341: =IFERROR(VLOOKUP(F341,'rt.comb'!$A:$B,2,FALSE),F341) -> 5.43 | H341: =IFERROR(VLOOKUP(G341,compounds!$A:$D,4,FALSE),"") -> hydroxymethylpentanone | I341: 383723762 | J341: =SUMIFS($I:$I,$A:$A,A341,G:G,19.5) -> 36699569 | K341: =VLOOKUP($C341,rosie!$B$7:$D$38,2,FALSE) -> 5.62 | L341: =VLOOKUP(C341,rosie!$B$7:$F$66,5,FALSE) -> 1.19 | M341: =VLOOKUP($C341,rosie!$B$7:$D$38,3,FALSE) -> 1 | N341: =VLOOKUP($C341,rosie!$B$7:$E$38,4,FALSE) -> l | O341: =IFERROR((30/J341*I341)/K341/Q341,0) -> 27.906969 | P341: =VLOOKUP(A341,RESULTS!$A:$M,13,FALSE) -> 1 | Q341: 2 | R341: =IF(VLOOKUP(C341,rosie!B:J,8,FALSE)=0,"x_x_x_x",VLOOKUP(C341,rosie!B:J,8,FALSE)) -> 5_5_31_2023
A342: 394-_-May-31-23 | C342: =VALUE(IF(B342="",LEFT(A342,FIND("-",A342)-1),B342)) -> 394 | D342: =C342&" ("&M342&")" -> 394 (1) | E342: 5.55 | F342: 5.55 | G342: =IFERROR(VLOOKUP(F342,'rt.comb'!$A:$B,2,FALSE),F342) -> 5.55 | H342: =IFERROR(VLOOKUP(G342,compounds!$A:$D,4,FALSE),"") | I342: 11888694 | J342: =SUMIFS($I:$I,$A:$A,A342,G:G,19.5) -> 36699569 | K342: =VLOOKUP($C342,rosie!$B$7:$D$38,2,FALSE) -> 5.62 | L342: =VLOOKUP(C342,rosie!$B$7:$F$66,5,FALSE) -> 1.19 | M342: =VLOOKUP($C342,rosie!$B$7:$D$38,3,FALSE) -> 1 | N342: =VLOOKUP($C342,rosie!$B$7:$E$38,4,FALSE) -> l | O342: =IFERROR((30/J342*I342)/K342/Q342,0) -> 0.86462568 | P342: =VLOOKUP(A342,RESULTS!$A:$M,13,FALSE) -> 1 | Q342: 2 | R342: =IF(VLOOKUP(C342,rosie!B:J,8,FALSE)=0,"x_x_x_x",VLOOKUP(C342,rosie!B:J,8,FALSE)) -> 5_5_31_2023
A343: 394-_-May-31-23 | C343: =VALUE(IF(B343="",LEFT(A343,FIND("-",A343)-1),B343)) -> 394 | D343: =C343&" ("&M343&")" -> 394 (1) | E343: 5.666 | F343: 5.67 | G343: =IFERROR(VLOOKUP(F343,'rt.comb'!$A:$B,2,FALSE),F343) -> 5.67 | H343: =IFERROR(VLOOKUP(G343,compounds!$A:$D,4,FALSE),"") | I343: 35099465 | J343: =SUMIFS($I:$I,$A:$A,A343,G:G,19.5) -> 36699569 | K343: =VLOOKUP($C343,rosie!$B$7:$D$38,2,FALSE) -> 5.62 | L343: =VLOOKUP(C343,rosie!$B$7:$F$66,5,FALSE) -> 1.19 | M343: =VLOOKUP($C343,rosie!$B$7:$D$38,3,FALSE) -> 1 | N343: =VLOOKUP($C343,rosie!$B$7:$E$38,4,FALSE) -> l | O343: =IFERROR((30/J343*I343)/K343/Q343,0) -> 2.5526688 | P343: =VLOOKUP(A343,RESULTS!$A:$M,13,FALSE) -> 1 | Q343: 2 | R343: =IF(VLOOKUP(C343,rosie!B:J,8,FALSE)=0,"x_x_x_x",VLOOKUP(C343,rosie!B:J,8,FALSE)) -> 5_5_31_2023
A344: 394-_-May-31-23 | C344: =VALUE(IF(B344="",LEFT(A344,FIND("-",A344)-1),B344)) -> 394 | D344: =C344&" ("&M344&")" -> 394 (1) | E344: 5.833 | F344: 5.83 | G344: =IFERROR(VLOOKUP(F344,'rt.comb'!$A:$B,2,FALSE),F344) -> 5.83 | H344: =IFERROR(VLOOKUP(G344,compounds!$A:$D,4,FALSE),"") | I344: 2715899369 | J344: =SUMIFS($I:$I,$A:$A,A344,G:G,19.5) -> 36699569 | K344: =VLOOKUP($C344,rosie!$B$7:$D$38,2,FALSE) -> 5.62 | L344: =VLOOKUP(C344,rosie!$B$7:$F$66,5,FALSE) -> 1.19 | M344: =VLOOKUP($C344,rosie!$B$7:$D$38,3,FALSE) -> 1 | N344: =VLOOKUP($C344,rosie!$B$7:$E$38,4,FALSE) -> l | O344: =IFERROR((30/J344*I344)/K344/Q344,0) -> 197.51844 | P344: =VLOOKUP(A344,RESULTS!$A:$M,13,FALSE) -> 1 | Q344: 2 | R344: =IF(VLOOKUP(C344,rosie!B:J,8,FALSE)=0,"x_x_x_x",VLOOKUP(C344,rosie!B:J,8,FALSE)) -> 5_5_31_2023
A345: 394-_-May-31-23 | C345: =VALUE(IF(B345="",LEFT(A345,FIND("-",A345)-1),B345)) -> 394 | D345: =C345&" ("&M345&")" -> 394 (1) | E345: 6.073 | F345: 6.07 | G345: =IFERROR(VLOOKUP(F345,'rt.comb'!$A:$B,2,FALSE),F345) -> 6.07 | H345: =IFERROR(VLOOKUP(G345,compounds!$A:$D,4,FALSE),"") | I345: 71552274 | J345: =SUMIFS($I:$I,$A:$A,A345,G:G,19.5) -> 36699569 | K345: =VLOOKUP($C345,rosie!$B$7:$D$38,2,FALSE) -> 5.62 | L345: =VLOOKUP(C345,rosie!$B$7:$F$66,5,FALSE) -> 1.19 | M345: =VLOOKUP($C345,rosie!$B$7:$D$38,3,FALSE) -> 1 | N345: =VLOOKUP($C345,rosie!$B$7:$E$38,4,FALSE) -> l | O345: =IFERROR((30/J345*I345)/K345/Q345,0) -> 5.2037619 | P345: =VLOOKUP(A345,RESULTS!$A:$M,13,FALSE) -> 1 | Q345: 2 | R345: =IF(VLOOKUP(C345,rosie!B:J,8,FALSE)=0,"x_x_x_x",VLOOKUP(C345,rosie!B:J,8,FALSE)) -> 5_5_31_2023
A346: 394-_-May-31-23 | C346: =VALUE(IF(B346="",LEFT(A346,FIND("-",A346)-1),B346)) -> 394 | D346: =C346&" ("&M346&")" -> 394 (1) | E346: 6.131 | F346: 6.13 | G346: =IFERROR(VLOOKUP(F346,'rt.comb'!$A:$B,2,FALSE),F346) -> 6.13 | H346: =IFERROR(VLOOKUP(G346,compounds!$A:$D,4,FALSE),"") | I346: 214445950 | J346: =SUMIFS($I:$I,$A:$A,A346,G:G,19.5) -> 36699569 | K346: =VLOOKUP($C346,rosie!$B$7:$D$38,2,FALSE) -> 5.62 | L346: =VLOOKUP(C346,rosie!$B$7:$F$66,5,FALSE) -> 1.19 | M346: =VLOOKUP($C346,rosie!$B$7:$D$38,3,FALSE) -> 1 | N346: =VLOOKUP($C346,rosie!$B$7:$E$38,4,FALSE) -> l | O346: =IFERROR((30/J346*I346)/K346/Q346,0) -> 15.59595 | P346: =VLOOKUP(A346,RESULTS!$A:$M,13,FALSE) -> 1 | Q346: 2 | R346: =IF(VLOOKUP(C346,rosie!B:J,8,FALSE)=0,"x_x_x_x",VLOOKUP(C346,rosie!B:J,8,FALSE)) -> 5_5_31_2023
A347: 394-_-May-31-23 | C347: =VALUE(IF(B347="",LEFT(A347,FIND("-",A347)-1),B347)) -> 394 | D347: =C347&" ("&M347&")" -> 394 (1) | E347: 6.727 | F347: 6.73 | G347: =IFERROR(VLOOKUP(F347,'rt.comb'!$A:$B,2,FALSE),F347) -> 6.73 | H347: =IFERROR(VLOOKUP(G347,compounds!$A:$D,4,FALSE),"") | I347: 8900748 | J347: =SUMIFS($I:$I,$A:$A,A347,G:G,19.5) -> 36699569 | K347: =VLOOKUP($C347,rosie!$B$7:$D$38,2,FALSE) -> 5.62 | L347: =VLOOKUP(C347,rosie!$B$7:$F$66,5,FALSE) -> 1.19 | M347: =VLOOKUP($C347,rosie!$B$7:$D$38,3,FALSE) -> 1 | N347: =VLOOKUP($C347,rosie!$B$7:$E$38,4,FALSE) -> l | O347: =IFERROR((30/J347*I347)/K347/Q347,0) -> 0.64732218 | P347: =VLOOKUP(A347,RESULTS!$A:$M,13,FALSE) -> 1 | Q347: 2 | R347: =IF(VLOOKUP(C347,rosie!B:J,8,FALSE)=0,"x_x_x_x",VLOOKUP(C347,rosie!B:J,8,FALSE)) -> 5_5_31_2023
A348: 394-_-May-31-23 | C348: =VALUE(IF(B348="",LEFT(A348,FIND("-",A348)-1),B348)) -> 394 | D348: =C348&" ("&M348&")" -> 394 (1) | E348: 6.972 | F348: 6.97 | G348: =IFERROR(VLOOKUP(F348,'rt.comb'!$A:$B,2,FALSE),F348) -> 6.97 | H348: =IFERROR(VLOOKUP(G348,compounds!$A:$D,4,FALSE),"") -> nonane | I348: 15803724 | J348: =SUMIFS($I:$I,$A:$A,A348,G:G,19.5) -> 36699569 | K348: =VLOOKUP($C348,rosie!$B$7:$D$38,2,FALSE) -> 5.62 | L348: =VLOOKUP(C348,rosie!$B$7:$F$66,5,FALSE) -> 1.19 | M348: =VLOOKUP($C348,rosie!$B$7:$D$38,3,FALSE) -> 1 | N348: =VLOOKUP($C348,rosie!$B$7:$E$38,4,FALSE) -> l | O348: =IFERROR((30/J348*I348)/K348/Q348,0) -> 1.149353 | P348: =VLOOKUP(A348,RESULTS!$A:$M,13,FALSE) -> 1 | Q348: 2 | R348: =IF(VLOOKUP(C348,rosie!B:J,8,FALSE)=0,"x_x_x_x",VLOOKUP(C348,rosie!B:J,8,FALSE)) -> 5_5_31_2023
A349: 394-_-May-31-23 | C349: =VALUE(IF(B349="",LEFT(A349,FIND("-",A349)-1),B349)) -> 394 | D349: =C349&" ("&M349&")" -> 394 (1) | E349: 7.1 | F349: 7.1 | G349: =IFERROR(VLOOKUP(F349,'rt.comb'!$A:$B,2,FALSE),F349) -> 7.1 | H349: =IFERROR(VLOOKUP(G349,compounds!$A:$D,4,FALSE),"") -> heptanal | I349: 18318790 | J349: =SUMIFS($I:$I,$A:$A,A349,G:G,19.5) -> 36699569 | K349: =VLOOKUP($C349,rosie!$B$7:$D$38,2,FALSE) -> 5.62 | L349: =VLOOKUP(C349,rosie!$B$7:$F$66,5,FALSE) -> 1.19 | M349: =VLOOKUP($C349,rosie!$B$7:$D$38,3,FALSE) -> 1 | N349: =VLOOKUP($C349,rosie!$B$7:$E$38,4,FALSE) -> l | O349: =IFERROR((30/J349*I349)/K349/Q349,0) -> 1.3322654 | P349: =VLOOKUP(A349,RESULTS!$A:$M,13,FALSE) -> 1 | Q349: 2 | R349: =IF(VLOOKUP(C349,rosie!B:J,8,FALSE)=0,"x_x_x_x",VLOOKUP(C349,rosie!B:J,8,FALSE)) -> 5_5_31_2023
... A524: 420-_-May-31-23 | C524: =VALUE(IF(B524="",LEFT(A524,FIND("-",A524)-1),B524)) -> 420 | D524: =C524&" ("&M524&")" -> 420 (1) | E524: 35.131 | F524: 35.13 | G524: =IFERROR(VLOOKUP(F524,'rt.comb'!$A:$B,2,FALSE),F524) -> 35.13 | H524: =IFERROR(VLOOKUP(G524,compounds!$A:$D,4,FALSE),"") | I524: 14993106 | J524: =SUMIFS($I:$I,$A:$A,A524,G:G,19.5) -> 32104763 | K524: =VLOOKUP($C524,rosie!$B$7:$D$38,2,FALSE) -> 7.77 | L524: =VLOOKUP(C524,rosie!$B$7:$F$66,5,FALSE) -> 1.78 | M524: =VLOOKUP($C524,rosie!$B$7:$D$38,3,FALSE) -> 1 | N524: =VLOOKUP($C524,rosie!$B$7:$E$38,4,FALSE) -> l | O524: =IFERROR((30/J524*I524)/K524/Q524,0) -> 0.90155533 | P524: =VLOOKUP(A524,RESULTS!$A:$M,13,FALSE) -> 1 | Q524: 2 | R524: =IF(VLOOKUP(C524,rosie!B:J,8,FALSE)=0,"x_x_x_x",VLOOKUP(C524,rosie!B:J,8,FALSE)) -> 6_5_31_2023
...

Sheet PIVOT2
B2: =IFERROR(VLOOKUP(B4,compounds!$A:$B,2,FALSE),"") | C2: =IFERROR(VLOOKUP(C4,compounds!$A:$B,2,FALSE),"") | D2: =IFERROR(VLOOKUP(D4,compounds!$A:$B,2,FALSE),"") | E2: =IFERROR(VLOOKUP(E4,compounds!$A:$B,2,FALSE),"") | F2: =IFERROR(VLOOKUP(F4,compounds!$A:$B,2,FALSE),"") | G2: =IFERROR(VLOOKUP(G4,compounds!$A:$B,2,FALSE),"") | H2: =IFERROR(VLOOKUP(H4,compounds!$A:$B,2,FALSE),"") | I2: =IFERROR(VLOOKUP(I4,compounds!$A:$B,2,FALSE),"") | ... AD2: =IFERROR(VLOOKUP(AD4,compounds!$A:$B,2,FALSE),"") | AF2: =IFERROR(VLOOKUP(AF4,compounds!$A:$B,2,FALSE),"") | AG2: =IFERROR(VLOOKUP(AG4,compounds!$A:$B,2,FALSE),"") | AH2: =IFERROR(VLOOKUP(AH4,compounds!$A:$B,2,FALSE),"") | AI2: =IFERROR(VLOOKUP(AI4,compounds!$A:$B,2,FALSE),"") | AJ2: =IFERROR(VLOOKUP(AJ4,compounds!$A:$B,2,FALSE),"") -> 4-hydroxy-4-methyl-2-pentanone | AK2: =IFERROR(VLOOKUP(AK4,compounds!$A:$B,2,FALSE),"") | AL2: =IFERROR(VLOOKUP(AL4,compounds!$A:$B,2,FALSE),"") | AM2: =IFERROR(VLOOKUP(AM4,compounds!$A:$B,2,FALSE),"") | ... VJ2: =IFERROR(VLOOKUP(VJ4,compounds!$A:$B,2,FALSE),"")
A3: Sum of area | B3: Column Labels
A4: Row Labels | B4: 4.11 | C4: 4.12 | D4: 4.22 | E4: 4.24 | F4: 4.25 | G4: 4.26 | H4: 4.27 | I4: 4.28 | J4: 4.29 | K4: 4.32 | L4: 4.36 | M4: 4.37 | N4: 4.38 | O4: 4.39 | P4: 4.4 | Q4: 4.52 | R4: 4.59 | S4: 4.61 | T4: 4.62 | U4: 4.63 | V4: 4.64 | W4: 4.66 | X4: 4.75 | Y4: 4.76 | Z4: 4.77 | AA4: 4.78 | AB4: 4.79 | AC4: 4.8 | AD4: 4.85 | AE4: 4.86 | AF4: 4.87 | AG4: 4.88 | AH4: 4.91 | AI4: 5.04 | AJ4: 5.43 | AK4: 5.55 | AL4: 5.65 | AM4: 5.66 | AN4: 5.67 | AO4: 5.71 | AP4: 5.74 | AQ4: 5.76 | AR4: 5.8 | AS4: 5.82 | AT4: 5.83 | AU4: 5.86 | AV4: 5.87 | AW4: 5.88 | AX4: 5.89 | AY4: 5.9 | AZ4: 5.96 | BA4: 6.05 | BB4: 6.07 | BC4: 6.11 | BD4: 6.13 | BE4: 6.44 | BF4: 6.45 | BG4: 6.46 | BH4: 6.49 | BI4: 6.72 | BJ4: 6.73 | BK4: 6.79 | BL4: 6.8 | BM4: 6.87 | BN4: 6.88 | BO4: 6.97 | BP4: 7.02 | BQ4: 7.03 | BR4: 7.07 | BS4: 7.1 | BT4: 7.47 | BU4: 7.51 | BV4: 7.56 | BW4: 7.57 | BX4: 7.58 | BY4: 7.81 | BZ4: 7.82 | CA4: 7.83 | CB4: 7.84 | CC4: 7.91 | CD4: 8.01 | CE4: 8.05 | CF4: 8.17 | CG4: 8.18 | CH4: 8.19 | CI4: 8.2 | CJ4: 8.21 | CK4: 8.22 | CL4: 8.23 | CM4: 8.38 | CN4: 8.39 | CO4: 8.46 | CP4: 8.47 | CQ4: 8.48 | CR4: 8.76 | CS4: 8.84 | CT4: 8.88 | CU4: 8.92 | CV4: 8.95 | CW4: 8.96 | CX4: 8.97 | CY4: 9.05 | CZ4: 9.06 | DA4: 9.3 | DB4: 9.31 | DC4: 9.32 | DD4: 9.37 | DE4: 9.39 | DF4: 9.54 | DG4: 9.55 | DH4: 9.82 | DI4: 9.9 | DJ4: 9.91 | DK4: 9.92 | DL4: 9.93 | DM4: 9.94 | DN4: 9.95 | DO4: 9.96 | DP4: 9.97 | DQ4: 9.98 | DR4: 10.01 | DS4: 10.16 | DT4: 10.26 | DU4: 10.31 | DV4: 10.33 | DW4: 10.34 | DX4: 10.35 | DY4: 10.36 | DZ4: 10.37 | EA4: 10.38 | EB4: 10.39 | EC4: 10.4 | ED4: 10.41 | EE4: 10.44 | EF4: 10.48 | EG4: 10.53 | EH4: 10.55 | EI4: 10.67 | EJ4: 10.68 | EK4: 10.72 | EL4: 10.74 | EM4: 10.75 | EN4: 10.76 | EO4: 10.77 | EP4: 10.78 | EQ4: 10.79 | ER4: 10.8 | ES4: 10.81 | ET4: 10.83 | EU4: 10.84 | EV4: 10.94 | EW4: 10.96 | EX4: 11.07 | EY4: 11.12 | EZ4: 11.15 | FA4: 11.18 | FB4: 11.19 | FC4: 11.22 | FD4: 11.24 | FE4: 11.26 | FF4: 11.27 | FG4: 11.28 | FH4: 11.31 | FI4: 11.32 | FJ4: 11.33 | FK4: 11.34 | FL4: 11.37 | FM4: 11.38 | FN4: 11.41 | FO4: 11.42 | FP4: 11.44 | FQ4: 11.45 | FR4: 11.46 | FS4: 11.47 | FT4: 11.48 | FU4: 11.52 | FV4: 11.58 | FW4: 11.59 | FX4: 11.6 | FY4: 11.76 | FZ4: 11.8 | GA4: 11.81 | GB4: 11.82 | GC4: 11.83 | GD4: 11.93 | GE4: 11.94 | GF4: 12.02 | GG4: 12.03 | GH4: 12.04 | GI4: 12.05 | GJ4: 12.06 | GK4: 12.07 | GL4: 12.08 | GM4: 12.09 | GN4: 12.1 | GO4: 12.11 | GP4: 12.29 | GQ4: 12.31 | GR4: 12.32 | GS4: 12.33 | GT4: 12.4 | GU4: 12.41 | GV4: 12.62 | GW4: 12.63 | GX4: 12.67 | GY4: 12.75 | GZ4: 12.76 | HA4: 12.86 | HB4: 12.88 | HC4: 12.99 | HD4: 13 | HE4: 13.01 | HF4: 13.1 | HG4: 13.17 | HH4: 13.18 | HI4: 13.2 | HJ4: 13.21 | HK4: 13.22 | HL4: 13.25 | HM4: 13.26 | HN4: 13.27 | HO4: 13.28 | HP4: 13.29 | HQ4: 13.3 | HR4: 13.31 | HS4: 13.35 | HT4: 13.36 | HU4: 13.37 | HV4: 13.38 | HW4: 13.39 | HX4: 13.43 | HY4: 13.44 | HZ4: 13.45 | IA4: 13.51 | IB4: 13.66 | IC4: 13.73 | ID4: 13.77 | IE4: 13.78 | IF4: 13.89 | IG4: 13.99 | IH4: 14.16 | II4: 14.17 | IJ4: 14.18 | IK4: 14.28 | IL4: 14.29 | IM4: 14.3 | IN4: 14.31 | IO4: 14.32 | IP4: 14.35 | IQ4: 14.38 | IR4: 14.39 | IS4: 14.51 | IT4: 14.52 | IU4: 14.53 | IV4: 14.54 | IW4: 14.55 | IX4: 14.56 | IY4: 14.63 | IZ4: 14.64 | JA4: 14.69 | JB4: 14.73 | JC4: 14.76 | JD4: 14.85 | JE4: 14.86 | JF4: 14.87 | JG4: 14.88 | JH4: 14.91 | JI4: 14.95 | JJ4: 14.97 | JK4: 15.06 | JL4: 15.07 | JM4: 15.11 | JN4: 15.12 | JO4: 15.13 | JP4: 15.16 | JQ4: 15.21 | JR4: 15.22 | JS4: 15.26 | JT4: 15.27 | JU4: 15.44 | JV4: 15.46 | JW4: 15.47 | JX4: 15.49 | JY4: 15.71 | JZ4: 15.9 | KA4: 15.93 | KB4: 15.94 | KC4: 16 | KD4: 16.02 | KE4: 16.03 | KF4: 16.04 | KG4: 16.1 | KH4: 16.11 | KI4: 16.12 | KJ4: 16.13 | KK4: 16.21 | KL4: 16.23 | KM4: 16.26 | KN4: 16.27 | KO4: 16.36 | KP4: 16.48 | KQ4: 16.55 | KR4: 16.73 | KS4: 16.74 | KT4: 16.75 | KU4: 16.84 | KV4: 16.85 | KW4: 16.91 | KX4: 16.92 | KY4: 16.93 | KZ4: 16.94 | LA4: 17.03 | LB4: 17.19 | LC4: 17.2 | LD4: 17.27 | LE4: 17.33 | LF4: 17.4 | LG4: 17.42 | LH4: 17.43 | LI4: 17.59 | LJ4: 17.63 | LK4: 17.64 | LL4: 17.65 | LM4: 17.91 | LN4: 17.92 | LO4: 17.93 | LP4: 18.05 | LQ4: 18.18 | LR4: 18.27 | LS4: 18.28 | LT4: 18.4 | LU4: 18.41 | LV4: 18.42 | LW4: 18.43 | LX4: 18.44 | LY4: 18.5 | LZ4: 18.51 | MA4: 18.52 | MB4: 18.59 | MC4: 18.65 | MD4: 18.67 | ME4: 18.69 | MF4: 18.77 | MG4: 18.95 | MH4: 18.96 | MI4: 18.97 | MJ4: 18.99 | MK4: 19.02 | ML4: 19.1 | MM4: 19.11 | MN4: 19.12 | MO4: 19.18 | MP4: 19.19 | MQ4: 19.27 | MR4: 19.28 | MS4: 19.4 | MT4: 19.45 | MU4: 19.5 | MV4: 19.59 | MW4: 19.76 | MX4: 19.88 | MY4: 19.9 | MZ4: 20.06 | NA4: 20.11 | NB4: 20.12 | NC4: 20.13 | ND4: 20.14 | NE4: 20.15 | NF4: 20.19 | NG4: 20.2 | NH4: 20.25 | NI4: 20.26 | NJ4: 20.27 | NK4: 20.28 | NL4: 20.33 | NM4: 20.36 | NN4: 20.39 | NO4: 20.6 | NP4: 20.61 | NQ4: 20.62 | NR4: 20.63 | NS4: 20.64 | NT4: 20.65 | NU4: 20.76 | NV4: 20.8 | NW4: 20.89 | NX4: 20.9 | NY4: 21.1 | NZ4: 21.11 | OA4: 21.18 | OB4: 21.23 | OC4: 21.24 | OD4: 21.26 | OE4: 21.28 | OF4: 21.29 | OG4: 21.33 | OH4: 21.37 | OI4: 21.38 | OJ4: 21.51 | OK4: 21.52 | OL4: 21.53 | OM4: 21.63 | ON4: 21.64 | OO4: 21.65 | OP4: 21.84 | OQ4: 21.98 | OR4: 21.99 | OS4: 22.03 | OT4: 22.04 | OU4: 22.07 | OV4: 22.17 | OW4: 22.29 | OX4: 22.3 | OY4: 22.31 | OZ4: 22.32 | PA4: 22.41 | PB4: 22.42 | PC4: 22.52 | PD4: 22.59 | PE4: 22.66 | PF4: 22.69 | PG4: 22.7 | PH4: 22.71 | PI4: 22.72 | PJ4: 22.73 | PK4: 22.8 | PL4: 22.82 | PM4: 22.9 | PN4: 22.99 | PO4: 23.1 | PP4: 23.11 | PQ4: 23.15 | PR4: 23.19 | PS4: 23.2 | PT4: 23.28 | PU4: 23.31 | PV4: 23.32 | PW4: 23.41 | PX4: 23.44 | PY4: 23.45 | PZ4: 23.46 | QA4: 23.52 | QB4: 23.54 | QC4: 23.67 | QD4: 23.8 | QE4: 23.84 | QF4: 23.85 | QG4: 23.88 | QH4: 23.9 | QI4: 23.91 | QJ4: 23.96 | QK4: 23.97 | QL4: 24.04 | QM4: 24.09 | QN4: 24.1 | QO4: 24.14 | QP4: 24.15 | QQ4: 24.24 | QR4: 24.25 | QS4: 24.33 | QT4: 24.34 | QU4: 24.41 | QV4: 24.42 | QW4: 24.43 | QX4: 24.6 | QY4: 24.62 | QZ4: 24.68 | RA4: 24.76 | RB4: 24.77 | RC4: 24.97 | RD4: 24.98 | RE4: 25.09 | RF4: 25.12 | RG4: 25.32 | RH4: 25.41 | RI4: 25.58 | RJ4: 25.89 | RK4: 26.06 | RL4: 26.07 | RM4: 26.24 | RN4: 26.25 | RO4: 26.31 | RP4: 26.36 | RQ4: 26.37 | RR4: 26.41 | RS4: 26.42 | RT4: 26.69 | RU4: 26.7 | RV4: 26.93 | RW4: 26.99 | RX4: 27.19 | RY4: 27.2 | RZ4: 27.38 | SA4: 27.54 | SB4: 28.2 | SC4: 28.21 | SD4: 28.36 | SE4: 28.43 | SF4: 28.44 | SG4: 28.51 | SH4: 28.79 | SI4: 28.82 | SJ4: 28.92 | SK4: 28.93 | SL4: 29.26 | SM4: 29.65 | SN4: 29.66 | SO4: 31.06 | SP4: 31.23 | SQ4: 31.24 | SR4: 31.25 | SS4: 31.42 | ST4: 31.61 | SU4: 31.62 | SV4: 32 | SW4: 32.01 | SX4: 32.38 | SY4: 32.39 | SZ4: 32.5 | TA4: 32.87 | TB4: 32.88 | TC4: 33.09 | TD4: 33.1 | TE4: 33.47 | TF4: 33.79 | TG4: 33.8 | TH4: 34.83 | TI4: 34.95 | TJ4: 35.09 | TK4: 35.1 | TL4: 35.13 | TM4: 35.84 | TN4: 36 | TO4: 36.01 | TP4: 36.07 | TQ4: 36.37 | TR4: 37.28 | TS4: 37.4 | TT4: 37.69 | TU4: 38.5 | TV4: 39.37 | TW4: 39.81 | TX4: (blank) | TY4: Grand Total
A5: 10 (0) | I5: 10547387 | L5: 367269522 | AJ5: 134868164 | AQ5: 830271702 | AU5: 287257859 | BC5: 67484218 | BI5: 11847345 | BO5: 20207509 | BS5: 63676011 | BU5: 15813038 | CP5: 11813817 | CU5: 41888710 | DH5: 18504210 | DU5: 168050066 | EF5: 1462325962 | EX5: 11190169 | EZ5: 43078746 | GP5: 27456319 | GU5: 23732517 | HI5: 15197547 | HW5: 15089006 | IA5: 587694068 | IB5: 16348691 | JP5: 7955249 | JX5: 33047875 | JY5: 11598706 | KC5: 35310067 | KK5: 19446732 | KO5: 23226888 | KQ5: 717673350 | LH5: 58779267 | LK5: 35717089 | LM5: 106338599 | LQ5: 47011345 | MB5: 43863998 | ME5: 25560303 | MJ5: 42675422 | ML5: 9375344 | MP5: 18026131 | MS5: 113846040 | MT5: 47293450 | MU5: 46115552 | NX5: 34750297 | NY5: 25435943 | OP5: 27361914 | OU5: 72333722 | OW5: 17773794 | PR5: 26544789 | QS5: 123416276 | QX5: 98914904 | RL5: 10108429 | RO5: 8189198 | RT5: 12387219 | RW5: 62914149 | RZ5: 12245955 | SH5: 17017741 | SK5: 56086396 | SL5: 137293088 | SQ5: 162757930 | SS5: 9624619 | SU5: 27358358 | SY5: 28897750 | SZ5: 12327502 | TB5: 358440965 | TI5: 12168932 | TL5: 86614349 | TQ5: 22410179 | TY5: 7157848388
A6: 1107 (1) | N6: 6943880 | AD6: 9831980 | AJ6: 63051647 | AL6: 9239216 | AQ6: 820051548 | BC6: 46127469 | BU6: 8210483 | CM6: 6119672 | CP6: 10988380 | CU6: 21750883 | DF6: 13476196 | DH6: 12788445 | DJ6: 13943313 | DS6: 10779076 | DX6: 72456147 | EF6: 198385434 | EK6: 9126748 | EV6: 10904369 | EX6: 4966584 | EZ6: 8993258 | GD6: 5548324 | GF6: 8093316 | GP6: 10773837 | HI6: 20691805 | HS6: 14351728 | IA6: 45709792 | IF6: 141169136 | JI6: 5804494 | JP6: 11210798 | KC6: 55866165 | KK6: 54998228 | KO6: 54876280 | KQ6: 49296916 | LE6: 19519312 | LH6: 52088963 | LQ6: 18048064 | ME6: 13860118 | MJ6: 19327459 | MU6: 34500202 | MX6: 18981866 | OJ6: 9266296 | OP6: 35171067 | OU6: 5555616 | OW6: 14831068 | PB6: 12056564 | QS6: 5053837 | RK6: 36871233 | SV6: 14090153 | TY6: 2145747365
A7: 1172 (0) | L7: 9931746 | P7: 7472488 | AF7: 29238131 | AJ7: 183125654 | AQ7: 146781955 | AW7: 29393202 | BS7: 7547455 | BU7: 15453571 | CN7: 5172546 | CP7: 9849935 | CU7: 30798531 | DH7: 4043839 | DU7: 54025950 | EF7: 33461019 | GP7: 15369092 | IA7: 157703398 | IF7: 32829788 | JT7: 9252052 | JX7: 8614478 | JY7: 7496827 | KK7: 14623965 | KO7: 15989316 | KQ7: 130048381 | LH7: 7683502 | LQ7: 32868695 | MB7: 6473101 | ME7: 24204433 | MJ7: 19536204 | MS7: 12165134 | MU7: 66859001 | NC7: 15220946 | NF7: 16379950 | OP7: 17375744 | OU7: 14787593 | OW7: 17928428 | PF7: 25413643 | PO7: 34743925 | QB7: 9834199 | QS7: 19862158 | QX7: 6289165 | RX7: 8325677 | SC7: 14019361 | SF7: 24714592 | SK7: 20036539 | SL7: 6995498 | SQ7: 16795845 | TB7: 39409527 | TJ7: 20566257 | TL7: 7795989 | TY7: 1464508425
A8: 1223 (1) | O8: 10731317 | AE8: 9582539 | AJ8: 9525220 | AQ8: 78232039 | AX8: 19524092 | BC8: 9635056 | BF8: 4549074 | BU8: 17120241 | CM8: 4213270 | CP8: 11395764 | CU8: 21360737 | DH8: 8742932 | DK8: 16374722 | DS8: 6184489 | DT8: 7755440 | DX8: 24929839 | EF8: 111615131 | EX8: 3823392 | GG8: 5475314 | HI8: 8808438 | HL8: 19187464 | IA8: 22754274 | IF8: 250551863 | JB8: 18820781 | JP8: 10680491 | KC8: 23426189 | KH8: 7273349 | KK8: 27996503 | KO8: 33128436 | KQ8: 21408844 | LE8: 95311371 | LH8: 34790087 | LQ8: 11376030 | MC8: -1978943 | MI8: 8868908 | MU8: 28108287 | MX8: 10646541 | NO8: 5135394 | OP8: 19300005 | OU8: 5893217 | OV8: 5888418 | OW8: 5507720 | PB8: 131210765 | PT8: 5184952 | QS8: 4099144 | RA8: 7890822 | RD8: 11290004 | RK8: 23903534 | RP8: 5493391 | RR8: 4346130 | SQ8: 5417973 | SV8: 6529986 | TJ8: 11061789 | TY8: 1270082765
A9: 13 (1) | D9: 2880155 | N9: 4716741 | R9: 5870122 | X9: 4526880 | AD9: 12823625 | AJ9: 6585236 | AQ9: 16418875 | AY9: 11707671 | BC9: 5970790 | BE9: 3386216 | BS9: 8073640 | BU9: 21847318 | CB9: 1193614 | CL9: 3084152 | CM9: 4205673 | CO9: 11105132 | CU9: 8036580 | DH9: 13749148 | DM9: 12323921 | DS9: 3027074 | DY9: 27958986 | EF9: 29865084 | EW9: 4724628 | FA9: 10755832 | GB9: 3384757 | GH9: 6960362 | GP9: 9085939 | HT9: 3840066 | IA9: 56161819 | IF9: 17084406 | IS9: 2792965 | JB9: 3805671 | JI9: 6416684 | JP9: 5212600 | JT9: 4898250 | JX9: 2899225 | JY9: 2660276 | KC9: 8047672 | KI9: 2760843 | KK9: 7216310 | KO9: 19149951 | KQ9: 50154660 | LE9: 12428321 | LH9: 15237714 | LO9: 2647463 | LQ9: 10236242 | MA9: 2916879 | MB9: 2002119 | MC9: 3033237 | ME9: 2767273 | MF9: 2313987 | MJ9: 4933543 | MP9: 3088846 | MS9: 5007190 | MU9: 26724218 | MX9: 5294596 | ND9: 1690207 | NP9: 3793314 | OF9: 9414864 | OM9: 2727386 | OP9: 22484005 | OU9: 5298650 | OW9: 16161676 | PB9: 3052187 | PG9: 3202431 | PL9: 2459751 | PP9: 3533156 | PR9: 4714989 | QE9: 1943863 | QN9: 1689866 | QR9: 2492936 | QS9: 5033215 | QX9: 3192829 | RF9: 2324344 | RL9: 5036651 | RT9: 6555883 | RW9: 2581885 | SB9: 4542348 | SK9: 2790390 | SQ9: 5614234 | SV9: 24006801 | TY9: 692339038
A10: 136 (0) | AF10: 59484057 | AQ10: 113657530 | BU10: 36769946 | BZ10: 360339995 | CD10: 1410315076 | CP10: 51509385 | DD10: 901115277 | DQ10: 6577197554 | ED10: 751330993 | ER10: 173624964 | FJ10: 17094200639 | FT10: 1383189510 | GB10: 3527410289 | GM10: 163885534 | GS10: 35162703 | GZ10: 33207426 | HE10: 732764836 | HN10: 160388079 | IA10: 206130453 | IF10: 1923545988 | IL10: 467316516 | IR10: 289877014 | IU10: 73525746 | IZ10: 126197753 | JI10: 688929223 | JM10: 216882744 | JV10: 95512287 | JY10: 89766613 | KE10: 192523826 | KK10: 82793799 | KO10: 191508566 | KQ10: 75022698 | KR10: 23205126 | KZ10: 201596920 | LB10: 233010356 | LL10: 100013615 | LO10: 20616945 | LQ10: 47721456 | LW10: 140180429 | ME10: 95785825 | ML10: 109266456 | MS10: 69016687 | MU10: 54720410 | MW10: 23732048 | NB10: 77432395 | NJ10: 63847723 | OB10: 41578275 | OH10: 40701754 | OP10: 24776020 | OT10: 77579561 | OZ10: 409295936 | PD10: 52315647 | PI10: 141154223 | PP10: 85064295 | PU10: 180542349 | QB10: 40768390 | QC10: 30603101 | QD10: 40248104 | QU10: 31735645 | QX10: 314128508 | RC10: 79588421 | RN10: 21906595 | RV10: 47805190 | SL10: 21518930 | TA10: 18546499 | TY10: 41245090853
A11: 140 (0) | I11: 7856625 | L11: 89231194 | AF11: 18159247 | AJ11: 94616773 | AQ11: 246403709 | BU11: 14954492 | CV11: 40578026 | DU11: 22690878 | EF11: 1452076393 | IA11: 83353925 | IF11: 12726375 | KK11: 17864320 | KO11: 13683037 | KQ11: 63520678 | LQ11: 20534086 | MJ11: 12211328 | MU11: 42224269 | OP11: 21789049 | OU11: 12240745 | PB11: 48767241 | QS11: 25538840 | SK11: 9126287 | SL11: 9534934 | TB11: 19141017 | TY11: 2398823468
A12: 147 (0) | K12: 8273246 | AC12: 23909272 | AJ12: 164360884 | AO12: 383379729 | AT12: 91416189 | BR12: 25987392 | BT12: 17047642 | CT12: 40202120 | DH12: 8926078 | DU12: 93306902 | EF12: 1685361528 | EI12: 27172118 | EX12: 9984551 | EZ12: 59114995 | FV12: 20962515 | GP12: 37722448 | GT12: 7322953 | HT12: 20867137 | HW12: 13619487 | IA12: 392369311 | JI12: 35859512 | JS12: 22225932 | JX12: 31803527 | JY12: 18925458 | KC12: 12772855 | KK12: 40872479 | KO12: 72170012 | KQ12: 349775327 | LH12: 106381080 | LN12: 13549661 | LQ12: 89830142 | MB12: 17916816 | ME12: 56629376 | MJ12: 26911368 | MS12: 43741792 | MT12: 27308959 | MU12: 42065388 | NC12: 39204389 | NF12: 40661145 | NX12: 14597362 | OO12: 17611639 | OP12: 57874188 | OU12: 63631882 | OW12: 18632073 | PF12: 82556398 | PO12: 103049699 | PR12: 21528499 | QB12: 14711496 | QS12: 20245218 | QX12: 26917351 | RT12: 15960908 | RW12: 19797229 | RX12: 15636258 | SK12: 10710680 | SL12: 30715250 | SQ12: 74486530 | SU12: 31041440 | TB12: 92332910 | TL12: 35876183 | TO12: 5164180 | TY12: 4992989088
A13: 16 (0) | AE13: 5030527 | AJ13: 30379210 | AQ13: 40570921 | AX13: 10362467 | BU13: 15271059 | CM13: 4508240 | CP13: 9060520 | CU13: 10764086 | DH13: 16145318 | DJ13: 20559267 | DU13: 12372271 | EX13: 2925488 | FY13: 14349702 | GG13: 6106575 | GP13: 4590413 | HM13: 11087866 | HT13: 7455023 | IA13: 46578642 | IF13: 264822220 | JD13: 9864349 | JI13: 6679970 | JP13: 8826822 | KC13: 9890474 | KH13: 9823636 | KK13: 22536456 | KO13: 33897019 | KQ13: 41100911 | LH13: 74870865 | LQ13: 5853329 | LZ13: 3555975 | MI13: 9590856 | MO13: 3904017 | MU13: 29702423 | NP13: 5758230 | OM13: 4667993 | OP13: 35162775 | OU13: 5018022 | OW13: 25389672 | PB13: 81282614 | PR13: 4413621 | QQ13: 3940090 | QS13: 7023519 | RA13: 17654362 | RC13: 16870115 | RT13: 7794089 | RW13: 3679089 | SJ13: 4112829 | SQ13: 16993017 | ST13: 6653395 | SV13: 46978800 | TN13: 2503610 | TY13: 1098932759
A14: 169 (0) | O14: 4825258 | AA14: 8866946 | AE14: 9394071 | AJ14: 60466784 | AQ14: 91801559 | AX14: 19602951 | BC14: 6621669 | BF14: 3872020 | BU14: 11314166 | BW14: 3225954 | CM14: 3878126 | CP14: 8234460 | CU14: 8710880 | DH14: 7903469 | DL14: 8804785 | DS14: 3906199 | DU14: 13851629 | DX14: 11189913 | EF14: 189179336 | EW14: 3882360 | GA14: 7950823 | GG14: 6002475 | HT14: 5177285 | IA14: 34008822 | IF14: 20876474 | JA14: 4798018 | JD14: 5109386 | JP14: 15422940 | JU14: 8177827 | KC14: 4036333 | KK14: 8321487 | KO14: 35115450 | KQ14: 35059368 | LH14: 17741466 | LQ14: 5040663 | MC14: 8058620 | MJ14: 14139689 | MP14: 2916112 | MQ14: 4289930 | MS14: 3157947 | MU14: 32928597 | MY14: 4029353 | ND14: 4186134 | NG14: 4554485 | NO14: 11277211 | OP14: 20945184 | OU14: 4786884 | OW14: 9272362 | PC14: 3215017 | PF14: 4073639 | PL14: 7262979 | PM14: 3554983 | PP14: 5841447 | PR14: 6878343 | QM14: 9585103 | QR14: 3731907 | QS14: 2963760 | RD14: 4435599 | RG14: 3140636 | RL14: 3659441 | RW14: 2930255 | SQ14: 10631377 | SV14: 5115267 | TA14: 2987013 | TJ14: 15989396 | TY14: 912910022
A15: 179 (1) | O15: 6975878 | AF15: 13167261 | AJ15: 14229651 | BM15: 26709963 | BU15: 8107366 | BZ15: 8559255 | CD15: 139465836 | CP15: 10195356 | DA15: 6708214 | DD15: 20381606 | DI15: 62845371 | DU15: 25430826 | EX15: 650380571 | FY15: 11017026 | GG15: 10729741 | IA15: 39650903 | IO15: 10500113 | IQ15: 6160243 | IT15: 6985142 | JP15: 7382129 | KQ15: 50467807 | KY15: 9696915 | LD15: 48594042 | LF15: 11662734 | LQ15: 33412968 | MA15: 30210419 | ME15: 25864012 | MK15: 14559601 | ML15: 267524828 | MS15: 6686960 | MU15: 47504927 | ND15: 5476723 | NM15: 8497342 | OW15: 34901972 | PG15: 8398086 | PP15: 7863994 | TY15: 1696905781
A16: 199 (0) | AJ16: 145040591 | AQ16: 80638465 | BC16: 85270223 | BU16: 32235697 | BY16: 138035666 | CD16: 214865402 | CP16: 34918694 | CU16: 31707454 | CY16: 30568204 | DB16: 121345981 | DD16: 130431034 | DN16: 4154260292 | EA16: 490324350 | EF16: 138137452 | EL16: 155662815 | FD16: 10391559923 | FP16: 613822213 | FY16: 1862962369 | GK16: 96697040 | GP16: 53048811 | HD16: 270618688 | HH16: 20004578 | HP16: 39851479 | HU16: 23215330 | HY16: 45370733 | IA16: 125430265 | IE16: 124856319 | IF16: 279800347 | IG16: 114140495 | II16: 76540345 | IL16: 140537273 | IR16: 314064325 | IU16: 59607941 | IY16: 78116913 | JE16: 22055265 | JI16: 291051742 | JM16: 91430885 | JV16: 62790244 | JY16: 70825145 | KA16: 35191350 | KE16: 41229527 | KG16: 48221877 | KM16: 105898161 | KO16: 200451540 | KQ16: 113603292 | KS16: 33273962 | KU16: 90139542 | KY16: 191977427 | LB16: 137308514 | LH16: 53875222 | LI16: 60636457 | LL16: 55034575 | LQ16: 36288584 | LX16: 116142103 | ME16: 64315673 | MJ16: 67586159 | ML16: 30824477 | MS16: 42540376 | MU16: 87889929 | NC16: 37580050 | NI16: 140933361 | OM16: 13452390 | OP16: 32108915 | OS16: 100494962 | OW16: 170714328 | PD16: 43260166 | PG16: 45652264 | PK16: 20637727 | PN16: 16588421 | PP16: 56752623 | PV16: 153480856 | PW16: 94996235 | QB16: 72212477 | QH16: 28439652 | QS16: 16524514 | QX16: 668793974 | RC16: 108288997 | RH16: 22375615 | RX16: 26421599 | SW16: 14100719 | TA16: 19426779 | TY16: 24767506359
A17: 221 (1) | AJ17: 32483682 | BY17: 413522289 | CD17: 682822454 | CY17: 94041661 | DB17: 309607373 | DD17: 394872565 | DO17: 5131793657 | EB17: 454458073 | EP17: 79836163 | EZ17: 6242564088 | FH17: 7779150287 | FR17: 156890343 | FY17: 333134199 | GL17: 71835256 | GP17: 31836562 | HD17: 218498054 | HG17: 21252784 | HQ17: 40386445 | HZ17: 104648657 | IA17: 87015819 | IE17: 149338070 | IF17: 132586981 | IG17: 271295787 | II17: 91766849 | IL17: 53180063 | IR17: 433036769 | IU17: 82192234 | IY17: 167677333 | JI17: 93593673 | JM17: 231254311 | JV17: 129684698 | JY17: 71775695 | KA17: 55729794 | KD17: 206598726 | KO17: 307637378 | KQ17: 121974977 | KR17: 39879170 | KV17: 134474470 | KY17: 319549453 | LB17: 365592786 | LL17: 140496826 | LQ17: 35940577 | LV17: 82043394 | LZ17: 63493311 | ME17: 103741693 | MJ17: 45558283 | ML17: 49197062 | MS17: 101488394 | MU17: 54213108 | MW17: 23952868 | NB17: 72242996 | NI17: 89867947 | OC17: 20095318 | OP17: 16765223 | OT17: 46786658 | OY17: 195485250 | PG17: 29085687 | PP17: 61312379 | PV17: 56377791 | PW17: 19817014 | QB17: 39382944 | QF17: 35364169 | QX17: 171760252 | RC17: 25495021 | TY17: 27719433793
A18: 222 (0) | O18: 41601435 | AF18: 15067341 | AJ18: 40900770 | AQ18: 50427320 | BU18: 40349931 | BZ18: 534981082 | CD18: 926698310 | CP18: 35391198 | CZ18: 136304132 | DB18: 259686165 | DD18: 321438786 | DO18: 4887471098 | DY18: 113196932 | EO18: 43226001 | FG18: 12651553090 | FQ18: 164016612 | FY18: 1106667444 | GK18: 75534221 | HD18: 394176592 | HG18: 26103943 | HN18: 124659569 | IA18: 110666614 | IE18: 254695635 | IF18: 1404560979 | IJ18: 50093393 | IL18: 55271477 | IR18: 703252818 | IU18: 73882340 | IY18: 60383358 | JT18: 96116922 | JV18: 44509016 | JY18: 103390787 | KA18: 38148429 | KD18: 171870994 | KO18: 596309460 | KQ18: 89688251 | KS18: 25877599 | KV18: 322444799 | KY18: 462504614 | LB18: 103793066 | LH18: 62485515 | LL18: 73695988 | LQ18: 90698040 | LW18: 32175931 | LZ18: 28902184 | ME18: 82339007 | MH18: 83221939 | ML18: 30591281 | MS18: 35620015 | MU18: 59814231 | NC18: 23175931 | NI18: 99636362 | OP18: 17082263 | OS18: 62126910 | OW18: 130035080 | PD18: 34007089 | PG18: 32494547 | PK18: 14141911 | PP18: 29267637 | PV18: 76793493 | PW18: 24444373 | QB18: 49117570 | QX18: 422108528 | RC18: 65391694 | RH18: 14294164 | SL18: 18448356 | TY18: 28449022562
A19: 246 (1) | E19: 6623850 | L19: 5244996 | O19: 12053314 | T19: 5820250 | AE19: 18951719 | AJ19: 128548384 | AQ19: 96563381 | AX19: 18563809 | BC19: 8893183 | BI19: 4399008 | BO19: 6560958 | BS19: 8422892 | BU19: 7304198 | CH19: 13995789 | CN19: 4414643 | CP19: 9529684 | CU19: 8167510 | CX19: 16324043 | DH19: 4144493 | DU19: 34228653 | EF19: 116322703 | EX19: 2680550 | HU19: 8663639 | IA19: 87072827 | IF19: 69477185 | JT19: 6356246 | KO19: 9953581 | KQ19: 100851466 | LQ19: 17600423 | MB19: 4913410 | ME19: 11009198 | MJ19: 12749293 | MP19: 5069709 | MS19: 9583854 | MT19: 14733721 | MU19: 30533038 | OP19: 17331953 | OU19: 10169281 | OW19: 8845866 | PS19: 6655393 | QS19: 27889274 | QX19: 5959300 | SK19: 7479553 | SL19: 7334901 | SQ19: 15897294 | TB19: 43028697 | TI19: 5756593 | TK19: 10983151 | TL19: 29175409 | TY19: 1122832265
A20: 247 (0) | I20: 16316492 | P20: 19645489 | V20: 6154850 | AF20: 5280326 | AJ20: 301930103 | AM20: 10401972 | AQ20: 591758040 | AV20: 122246862 | BC20: 41037581 | BI20: 13674541 | BO20: 18728093 | BS20: 17470397 | BU20: 10611613 | CG20: 14763021 | CN20: 6512066 | CP20: 12963522 | CU20: 38633631 | DH20: 19270561 | DK20: 26212646 | DS20: 7742926 | DU20: 64002560 | EF20: 38747766 | EX20: 9611154 | EY20: 60184831 | GP20: 49560669 | HS20: 27469233 | IA20: 173084092 | IF20: 24842768 | JP20: 10072646 | JS20: 23226275 | JX20: 11654762 | JY20: 13043040 | KK20: 22856215 | KO20: 39089905 | KQ20: 175201579 | LA20: 12665114 | LH20: 43274917 | LN20: 47181171 | LQ20: 94146815 | MB20: 9323721 | ME20: 47631201 | MJ20: 43172644 | MP20: 12191866 | MS20: 27200300 | MT20: 42628387 | MU20: 57141843 | NC20: 6380808 | NX20: 9975318 | OM20: 9546749 | OP20: 63712550 | OU20: 24440419 | OW20: 20865605 | PF20: 15464252 | PP20: 12275872 | PR20: 8678020 | QP20: 9834953 | QS20: 74879163 | QX20: 45812639 | RL20: 5440561 | RT20: 22554280 | RW20: 37245003 | RX20: 13488017 | SC20: 14584093 | SH20: 11084096 | SK20: 45963968 | SL20: 96763481 | SM20: 10831787 | SO20: 7273736 | SQ20: 70428443 | SS20: 11224233 | SU20: 9482118 | SW20: 7875459 | SY20: 16838957 | TB20: 223549124 | TC20: 14767302 | TE20: 11160976 | TF20: 5880275 | TH20: 3595483 | TI20: 8971729 | TK20: 34981823 | TL20: 63337977 | TM20: 733619 | TP20: 3634108 | TQ20: 31993430 | TR20: 12868477 | TT20: 6759505 | TW20: 6978818 | TY20: 3592717432
A21: 25 (1) | O21: 3221513 | T21: 1092089 | AE21: 6398430 | AJ21: 53581516 | AQ21: 24184505 | AX21: 5326514 | AZ21: 4547738 | BF21: 1077794 | BP21: 2475373 | BS21: 4236266 | BU21: 11660114 | BV21: 3573912 | CM21: 3842764 | CP21: 8465577 | CU21: 8802623 | DH21: 8112129 | DM21: 12399915 | DS21: 5237861 | DU21: 23663748 | EF21: 34409050 | EW21: 4080444 | EX21: 3065680 | EZ21: 13342379 | FX21: 4847775 | FY21: 4077946 | GA21: 6065084 | GG21: 7334594 | GP21: 17683099 | HA21: 2881247 | HI21: 4554974 | HT21: 10062548 | HX21: 3999217 | IA21: 51641179 | IF21: 27911963 | IP21: 2725439 | IS21: 2936061 | JB21: 3703280 | JE21: 3202759 | JI21: 9329926 | JP21: 7082439 | JT21: 3059863 | JU21: 2504742 | JY21: 2489411 | KC21: 4575584 | KI21: 3296925 | KK21: 5812044 | KO21: 39236142 | KQ21: 43997854 | LE21: 5129225 | LH21: 9050054 | LQ21: 7416443 | MA21: 2545933 | MC21: 4096983 | ME21: 3371248 | MJ21: 14755636 | MP21: 4939973 | MR21: 3373322 | MS21: 3926197 | MU21: 30635289 | MY21: 3613299 | ND21: 4732812 | NG21: 6363833 | NO21: 5208598 | OF21: 4761724 | OM21: 5273488 | OP21: 56190980 | OU21: 5975421 | OW21: 24223841 | PB21: 14489076 | PG21: 5535057 | PL21: 3114866 | PP21: 8144758 | PR21: 3882951 | QN21: 5036810 | QO21: 4441963 | QR21: 2827740 | QS21: 6820889 | QX21: 3146845 | RD21: 3004670 | RI21: 2583279 | RL21: 3154023 | RT21: 10785582 | RW21: 3909131 | SB21: 12342501 | SE21: 2530306 | SI21: 4611558 | SJ21: 2456107 | SQ21: 39463705 | ST21: 8982206 | SV21: 17708879 | SX21: 5144290 | TA21: 82545110 | TY21: 984056630
