Workbook

Sheet RAW
A1: Sample | B1: Header= | C1: Peak | D1: RT | E1: RT_round | F1: First | G1: Max | H1: Last | I1: PK TY | J1: Height | K1: Area | L1: Pct Max | M1: Pct Total
A2: 10A-4B-VCS-Loc-22 | B2: 1= | C2: 1 | D2: 4.168 | E2: =ROUND(D2,2) -> 4.17 | F2: 5 | G2: 26 | H2: 86 | I2: BB 5 | J2: 227762 | K2: 3806407 | L2: 6.53 | M2: 0.769
A3: 10A-4B-VCS-Loc-22 | B3: 2= | C3: 2 | D3: 4.451 | E3: =ROUND(D3,2) -> 4.45 | F3: 98 | G3: 115 | H3: 133 | I3: BV 9 | J3: 25013 | K3: 861335 | L3: 1.48 | M3: 0.174
A4: 10A-4B-VCS-Loc-22 | B4: 3= | C4: 3 | D4: 4.719 | E4: =ROUND(D4,2) -> 4.72 | F4: 194 | G4: 200 | H4: 273 | I4: BV 4 | J4: 154389 | K4: 5185464 | L4: 8.89 | M4: 1.047
A5: 10A-4B-VCS-Loc-22 | B5: 4= | C5: 4 | D5: 5.028 | E5: =ROUND(D5,2) -> 5.03 | F5: 273 | G5: 298 | H5: 342 | I5: PV 8 | J5: 169743 | K5: 6976344 | L5: 11.97 | M5: 1.409
A6: 10A-4B-VCS-Loc-22 | B6: 5= | C6: 5 | D6: 5.197 | E6: =ROUND(D6,2) -> 5.2 | F6: 342 | G6: 351 | H6: 379 | I6: VV 9 | J6: 50081 | K6: 1485790 | L6: 2.55 | M6: 0.3
A7: 10A-4B-VCS-Loc-22 | B7: 6= | C7: 6 | D7: 6.269 | E7: =ROUND(D7,2) -> 6.27 | F7: 665 | G7: 690 | H7: 701 | I7: PV 9 | J7: 37451 | K7: 1584035 | L7: 2.72 | M7: 0.32
A8: 10A-4B-VCS-Loc-22 | B8: 7= | C8: 7 | D8: 6.332 | E8: =ROUND(D8,2) -> 6.33 | F8: 701 | G8: 710 | H8: 732 | I8: VV 9 | J8: 80344 | K8: 3224612 | L8: 5.53 | M8: 0.651
A9: 10A-4B-VCS-Loc-22 | B9: 8= | C9: 8 | D9: 6.423 | E9: =ROUND(D9,2) -> 6.42 | F9: 732 | G9: 739 | H9: 790 | I9: VV 9 | J9: 46052 | K9: 2660289 | L9: 4.56 | M9: 0.537
A10: 10A-4B-VCS-Loc-22 | B10: 9= | C10: 9 | D10: 8.648 | E10: =ROUND(D10,2) -> 8.65 | F10: 1428 | G10: 1442 | H10: 1487 | I10: BB 6 | J10: 41001 | K10: 2130604 | L10: 3.65 | M10: 0.43
A11: 10A-4B-VCS-Loc-22 | B11: 10= | C11: 10 | D11: 8.972 | E11: =ROUND(D11,2) -> 8.97 | F11: 1523 | G11: 1545 | H11: 1606 | I11: VB 6 | J11: 53373 | K11: 3694102 | L11: 6.34 | M11: 0.746
A12: 10A-4B-VCS-Loc-22 | B12: 11= | C12: 11 | D12: 9.381 | E12: =ROUND(D12,2) -> 9.38 | F12: 1652 | G12: 1674 | H12: 1717 | I12: BV 9 | J12: 139477 | K12: 7243660 | L12: 12.43 | M12: 1.463
A13: 10A-4B-VCS-Loc-22 | B13: 12= | C13: 12 | D13: 9.561 | E13: =ROUND(D13,2) -> 9.56 | F13: 1717 | G13: 1731 | H13: 1757 | I13: VV 5 | J13: 84253 | K13: 3833068 | L13: 6.57 | M13: 0.774
... A4977: 9E-25A-VCS-Loc-22 | B4977: 79= | C4977: 79 | D4977: 40.013 | E4977: =ROUND(D4977,2) -> 40.01 | F4977: 11350 | G4977: 11362 | H4977: 11390 | I4977: VV 2 | J4977: 47095 | K4977: 1258212 | L4977: 1.12 | M4977: 0.207

Sheet RAW2
A1: sample_ID | B1: plant.id | C1: rt | D1: rt_round | E1: rt_comb | F1: rt.final | G1: area | H1: control_area | I1: replicate | J1: position | K1: sample | L1: biomass | M1: leaf_count | N1: wet_wt | O1: swa | P1: id | Q1: ngghr | R1: fortbl | S1: Sample | T1: remove | U1: compound | V1: pair
A2: 10A-4B-VCS-Loc-22 | B2: =LEFT(A2,FIND("-",A2)-1) -> 10A | C2: 4.168 | D2: =ROUND(C2,2) -> 4.17 | E2: =VLOOKUP(D2,'Peak Combiner'!$A$5:$D$4980,4,FALSE) -> 4.15 | F2: =IFERROR(VLOOKUP(D2,rt_comb!$A:$B,2,FALSE),D2) -> 4.17 | G2: 3806407 | H2: =SUMIFS($G:$G,$E:$E,18.51,'RAW2'!$A:$A,'RAW2'!A2) -> 42551864 | I2: =VLOOKUP(A2,'volatile collection data'!$G$6:$H$69,2,FALSE) -> A | J2: =VLOOKUP(A2,'volatile collection data'!$G$6:$I$69,3,FALSE) -> 10 | K2: =VLOOKUP(A2,'volatile collection data'!$G$6:$N$69,8,FALSE) -> 4B | L2: =VLOOKUP(A2,'volatile collection data'!$G$6:$J$69,4,FALSE) -> 3.8 | M2: =VLOOKUP($A2,'volatile collection data'!$G$6:$M$69,6,FALSE) -> 8 | N2: =VLOOKUP($A2,'volatile collection data'!$G$6:$M$69,7,FALSE) -> 3.8 | O2: =VLOOKUP(A2,'volatile collection data'!$G$6:$K$69,5,FALSE) -> 0 | P2: =J2&I2 -> 10A | Q2: =IFERROR((30/H2*G2)/L2/6,0) -> 0.11770178 | R2: =K2&"_"&O2&"-"&I2&"&"&L2&"%"&N2&"@"&M2 -> 4B_0-A&3.8%3.8@8 | S2: =A2 -> 10A-4B-VCS-Loc-22 | T2: =IFERROR(IF(VLOOKUP(S2,Bad!$A:$A,1,FALSE)='RAW2'!S2,"yes","no"),"no") -> no | U2: =IFERROR(VLOOKUP(F2,compounds!$A:$B,2,FALSE),"") | V2: =VLOOKUP(B2,'volatile collection data'!$O:$P,2,FALSE) -> 24.apr.22 4
A3: 10A-4B-VCS-Loc-22 | B3: =LEFT(A3,FIND("-",A3)-1) -> 10A | C3: 4.451 | D3: =ROUND(C3,2) -> 4.45 | E3: =VLOOKUP(D3,'Peak Combiner'!$A$5:$D$4980,4,FALSE) -> 4.45 | F3: =IFERROR(VLOOKUP(D3,rt_comb!$A:$B,2,FALSE),D3) -> 4.45 | G3: 861335 | H3: =SUMIFS($G:$G,$E:$E,18.51,'RAW2'!$A:$A,'RAW2'!A3) -> 42551864 | I3: =VLOOKUP(A3,'volatile collection data'!$G$6:$H$69,2,FALSE) -> A | J3: =VLOOKUP(A3,'volatile collection data'!$G$6:$I$69,3,FALSE) -> 10 | K3: =VLOOKUP(A3,'volatile collection data'!$G$6:$N$69,8,FALSE) -> 4B | L3: =VLOOKUP(A3,'volatile collection data'!$G$6:$J$69,4,FALSE) -> 3.8 | M3: =VLOOKUP($A3,'volatile collection data'!$G$6:$M$69,6,FALSE) -> 8 | N3: =VLOOKUP($A3,'volatile collection data'!$G$6:$M$69,7,FALSE) -> 3.8 | O3: =VLOOKUP(A3,'volatile collection data'!$G$6:$K$69,5,FALSE) -> 0 | P3: =J3&I3 -> 10A | Q3: =IFERROR((30/H3*G3)/L3/6,0) -> 0.026634216 | R3: =K3&"_"&O3&"-"&I3&"&"&L3&"%"&N3&"@"&M3 -> 4B_0-A&3.8%3.8@8 | S3: =A3 -> 10A-4B-VCS-Loc-22 | T3: =IFERROR(IF(VLOOKUP(S3,Bad!$A:$A,1,FALSE)='RAW2'!S3,"yes","no"),"no") -> no | U3: =IFERROR(VLOOKUP(F3,compounds!$A:$B,2,FALSE),"") | V3: =VLOOKUP(B3,'volatile collection data'!$O:$P,2,FALSE) -> 24.apr.22 4
A4: 10A-4B-VCS-Loc-22 | B4: =LEFT(A4,FIND("-",A4)-1) -> 10A | C4: 4.719 | D4: =ROUND(C4,2) -> 4.72 | E4: =VLOOKUP(D4,'Peak Combiner'!$A$5:$D$4980,4,FALSE) -> 4.7 | F4: =IFERROR(VLOOKUP(D4,rt_comb!$A:$B,2,FALSE),D4) -> 4.72 | G4: 5185464 | H4: =SUMIFS($G:$G,$E:$E,18.51,'RAW2'!$A:$A,'RAW2'!A4) -> 42551864 | I4: =VLOOKUP(A4,'volatile collection data'!$G$6:$H$69,2,FALSE) -> A | J4: =VLOOKUP(A4,'volatile collection data'!$G$6:$I$69,3,FALSE) -> 10 | K4: =VLOOKUP(A4,'volatile collection data'!$G$6:$N$69,8,FALSE) -> 4B | L4: =VLOOKUP(A4,'volatile collection data'!$G$6:$J$69,4,FALSE) -> 3.8 | M4: =VLOOKUP($A4,'volatile collection data'!$G$6:$M$69,6,FALSE) -> 8 | N4: =VLOOKUP($A4,'volatile collection data'!$G$6:$M$69,7,FALSE) -> 3.8 | O4: =VLOOKUP(A4,'volatile collection data'!$G$6:$K$69,5,FALSE) -> 0 | P4: =J4&I4 -> 10A | Q4: =IFERROR((30/H4*G4)/L4/6,0) -> 0.16034501 | R4: =K4&"_"&O4&"-"&I4&"&"&L4&"%"&N4&"@"&M4 -> 4B_0-A&3.8%3.8@8 | S4: =A4 -> 10A-4B-VCS-Loc-22 | T4: =IFERROR(IF(VLOOKUP(S4,Bad!$A:$A,1,FALSE)='RAW2'!S4,"yes","no"),"no") -> no | U4: =IFERROR(VLOOKUP(F4,compounds!$A:$B,2,FALSE),"") | V4: =VLOOKUP(B4,'volatile collection data'!$O:$P,2,FALSE) -> 24.apr.22 4
A5: 10A-4B-VCS-Loc-22 | B5: =LEFT(A5,FIND("-",A5)-1) -> 10A | C5: 5.028 | D5: =ROUND(C5,2) -> 5.03 | E5: =VLOOKUP(D5,'Peak Combiner'!$A$5:$D$4980,4,FALSE) -> 5.03 | F5: =IFERROR(VLOOKUP(D5,rt_comb!$A:$B,2,FALSE),D5) -> 5.03 | G5: 6976344 | H5: =SUMIFS($G:$G,$E:$E,18.51,'RAW2'!$A:$A,'RAW2'!A5) -> 42551864 | I5: =VLOOKUP(A5,'volatile collection data'!$G$6:$H$69,2,FALSE) -> A | J5: =VLOOKUP(A5,'volatile collection data'!$G$6:$I$69,3,FALSE) -> 10 | K5: =VLOOKUP(A5,'volatile collection data'!$G$6:$N$69,8,FALSE) -> 4B | L5: =VLOOKUP(A5,'volatile collection data'!$G$6:$J$69,4,FALSE) -> 3.8 | M5: =VLOOKUP($A5,'volatile collection data'!$G$6:$M$69,6,FALSE) -> 8 | N5: =VLOOKUP($A5,'volatile collection data'!$G$6:$M$69,7,FALSE) -> 3.8 | O5: =VLOOKUP(A5,'volatile collection data'!$G$6:$K$69,5,FALSE) -> 0 | P5: =J5&I5 -> 10A | Q5: =IFERROR((30/H5*G5)/L5/6,0) -> 0.21572263 | R5: =K5&"_"&O5&"-"&I5&"&"&L5&"%"&N5&"@"&M5 -> 4B_0-A&3.8%3.8@8 | S5: =A5 -> 10A-4B-VCS-Loc-22 | T5: =IFERROR(IF(VLOOKUP(S5,Bad!$A:$A,1,FALSE)='RAW2'!S5,"yes","no"),"no") -> no | U5: =IFERROR(VLOOKUP(F5,compounds!$A:$B,2,FALSE),"") | V5: =VLOOKUP(B5,'volatile collection data'!$O:$P,2,FALSE) -> 24.apr.22 4
A6: 10A-4B-VCS-Loc-22 | B6: =LEFT(A6,FIND("-",A6)-1) -> 10A | C6: 5.197 | D6: =ROUND(C6,2) -> 5.2 | E6: =VLOOKUP(D6,'Peak Combiner'!$A$5:$D$4980,4,FALSE) -> 5.2 | F6: =IFERROR(VLOOKUP(D6,rt_comb!$A:$B,2,FALSE),D6) -> 5.2 | G6: 1485790 | H6: =SUMIFS($G:$G,$E:$E,18.51,'RAW2'!$A:$A,'RAW2'!A6) -> 42551864 | I6: =VLOOKUP(A6,'volatile collection data'!$G$6:$H$69,2,FALSE) -> A | J6: =VLOOKUP(A6,'volatile collection data'!$G$6:$I$69,3,FALSE) -> 10 | K6: =VLOOKUP(A6,'volatile collection data'!$G$6:$N$69,8,FALSE) -> 4B | L6: =VLOOKUP(A6,'volatile collection data'!$G$6:$J$69,4,FALSE) -> 3.8 | M6: =VLOOKUP($A6,'volatile collection data'!$G$6:$M$69,6,FALSE) -> 8 | N6: =VLOOKUP($A6,'volatile collection data'!$G$6:$M$69,7,FALSE) -> 3.8 | O6: =VLOOKUP(A6,'volatile collection data'!$G$6:$K$69,5,FALSE) -> 0 | P6: =J6&I6 -> 10A | Q6: =IFERROR((30/H6*G6)/L6/6,0) -> 0.045943624 | R6: =K6&"_"&O6&"-"&I6&"&"&L6&"%"&N6&"@"&M6 -> 4B_0-A&3.8%3.8@8 | S6: =A6 -> 10A-4B-VCS-Loc-22 | T6: =IFERROR(IF(VLOOKUP(S6,Bad!$A:$A,1,FALSE)='RAW2'!S6,"yes","no"),"no") -> no | U6: =IFERROR(VLOOKUP(F6,compounds!$A:$B,2,FALSE),"") | V6: =VLOOKUP(B6,'volatile collection data'!$O:$P,2,FALSE) -> 24.apr.22 4
A7: 10A-4B-VCS-Loc-22 | B7: =LEFT(A7,FIND("-",A7)-1) -> 10A | C7: 6.269 | D7: =ROUND(C7,2) -> 6.27 | E7: =VLOOKUP(D7,'Peak Combiner'!$A$5:$D$4980,4,FALSE) -> 6.25 | F7: =IFERROR(VLOOKUP(D7,rt_comb!$A:$B,2,FALSE),D7) -> 6.27 | G7: 1584035 | H7: =SUMIFS($G:$G,$E:$E,18.51,'RAW2'!$A:$A,'RAW2'!A7) -> 42551864 | I7: =VLOOKUP(A7,'volatile collection data'!$G$6:$H$69,2,FALSE) -> A | J7: =VLOOKUP(A7,'volatile collection data'!$G$6:$I$69,3,FALSE) -> 10 | K7: =VLOOKUP(A7,'volatile collection data'!$G$6:$N$69,8,FALSE) -> 4B | L7: =VLOOKUP(A7,'volatile collection data'!$G$6:$J$69,4,FALSE) -> 3.8 | M7: =VLOOKUP($A7,'volatile collection data'!$G$6:$M$69,6,FALSE) -> 8 | N7: =VLOOKUP($A7,'volatile collection data'!$G$6:$M$69,7,FALSE) -> 3.8 | O7: =VLOOKUP(A7,'volatile collection data'!$G$6:$K$69,5,FALSE) -> 0 | P7: =J7&I7 -> 10A | Q7: =IFERROR((30/H7*G7)/L7/6,0) -> 0.048981558 | R7: =K7&"_"&O7&"-"&I7&"&"&L7&"%"&N7&"@"&M7 -> 4B_0-A&3.8%3.8@8 | S7: =A7 -> 10A-4B-VCS-Loc-22 | T7: =IFERROR(IF(VLOOKUP(S7,Bad!$A:$A,1,FALSE)='RAW2'!S7,"yes","no"),"no") -> no | U7: =IFERROR(VLOOKUP(F7,compounds!$A:$B,2,FALSE),"") | V7: =VLOOKUP(B7,'volatile collection data'!$O:$P,2,FALSE) -> 24.apr.22 4
A8: 10A-4B-VCS-Loc-22 | B8: =LEFT(A8,FIND("-",A8)-1) -> 10A | C8: 6.332 | D8: =ROUND(C8,2) -> 6.33 | E8: =VLOOKUP(D8,'Peak Combiner'!$A$5:$D$4980,4,FALSE) -> 6.32 | F8: =IFERROR(VLOOKUP(D8,rt_comb!$A:$B,2,FALSE),D8) -> 6.33 | G8: 3224612 | H8: =SUMIFS($G:$G,$E:$E,18.51,'RAW2'!$A:$A,'RAW2'!A8) -> 42551864 | I8: =VLOOKUP(A8,'volatile collection data'!$G$6:$H$69,2,FALSE) -> A | J8: =VLOOKUP(A8,'volatile collection data'!$G$6:$I$69,3,FALSE) -> 10 | K8: =VLOOKUP(A8,'volatile collection data'!$G$6:$N$69,8,FALSE) -> 4B | L8: =VLOOKUP(A8,'volatile collection data'!$G$6:$J$69,4,FALSE) -> 3.8 | M8: =VLOOKUP($A8,'volatile collection data'!$G$6:$M$69,6,FALSE) -> 8 | N8: =VLOOKUP($A8,'volatile collection data'!$G$6:$M$69,7,FALSE) -> 3.8 | O8: =VLOOKUP(A8,'volatile collection data'!$G$6:$K$69,5,FALSE) -> 0 | P8: =J8&I8 -> 10A | Q8: =IFERROR((30/H8*G8)/L8/6,0) -> 0.099711508 | R8: =K8&"_"&O8&"-"&I8&"&"&L8&"%"&N8&"@"&M8 -> 4B_0-A&3.8%3.8@8 | S8: =A8 -> 10A-4B-VCS-Loc-22 | T8: =IFERROR(IF(VLOOKUP(S8,Bad!$A:$A,1,FALSE)='RAW2'!S8,"yes","no"),"no") -> no | U8: =IFERROR(VLOOKUP(F8,compounds!$A:$B,2,FALSE),"") | V8: =VLOOKUP(B8,'volatile collection data'!$O:$P,2,FALSE) -> 24.apr.22 4
A9: 10A-4B-VCS-Loc-22 | B9: =LEFT(A9,FIND("-",A9)-1) -> 10A | C9: 6.423 | D9: =ROUND(C9,2) -> 6.42 | E9: =VLOOKUP(D9,'Peak Combiner'!$A$5:$D$4980,4,FALSE) -> 6.42 | F9: =IFERROR(VLOOKUP(D9,rt_comb!$A:$B,2,FALSE),D9) -> 6.42 | G9: 2660289 | H9: =SUMIFS($G:$G,$E:$E,18.51,'RAW2'!$A:$A,'RAW2'!A9) -> 42551864 | I9: =VLOOKUP(A9,'volatile collection data'!$G$6:$H$69,2,FALSE) -> A | J9: =VLOOKUP(A9,'volatile collection data'!$G$6:$I$69,3,FALSE) -> 10 | K9: =VLOOKUP(A9,'volatile collection data'!$G$6:$N$69,8,FALSE) -> 4B | L9: =VLOOKUP(A9,'volatile collection data'!$G$6:$J$69,4,FALSE) -> 3.8 | M9: =VLOOKUP($A9,'volatile collection data'!$G$6:$M$69,6,FALSE) -> 8 | N9: =VLOOKUP($A9,'volatile collection data'!$G$6:$M$69,7,FALSE) -> 3.8 | O9: =VLOOKUP(A9,'volatile collection data'!$G$6:$K$69,5,FALSE) -> 0 | P9: =J9&I9 -> 10A | Q9: =IFERROR((30/H9*G9)/L9/6,0) -> 0.082261502 | R9: =K9&"_"&O9&"-"&I9&"&"&L9&"%"&N9&"@"&M9 -> 4B_0-A&3.8%3.8@8 | S9: =A9 -> 10A-4B-VCS-Loc-22 | T9: =IFERROR(IF(VLOOKUP(S9,Bad!$A:$A,1,FALSE)='RAW2'!S9,"yes","no"),"no") -> no | U9: =IFERROR(VLOOKUP(F9,compounds!$A:$B,2,FALSE),"") | V9: =VLOOKUP(B9,'volatile collection data'!$O:$P,2,FALSE) -> 24.apr.22 4
A10: 10A-4B-VCS-Loc-22 | B10: =LEFT(A10,FIND("-",A10)-1) -> 10A | C10: 8.648 | D10: =ROUND(C10,2) -> 8.65 | E10: =VLOOKUP(D10,'Peak Combiner'!$A$5:$D$4980,4,FALSE) -> 8.64 | F10: =IFERROR(VLOOKUP(D10,rt_comb!$A:$B,2,FALSE),D10) -> 8.65 | G10: 2130604 | H10: =SUMIFS($G:$G,$E:$E,18.51,'RAW2'!$A:$A,'RAW2'!A10) -> 42551864 | I10: =VLOOKUP(A10,'volatile collection data'!$G$6:$H$69,2,FALSE) -> A | J10: =VLOOKUP(A10,'volatile collection data'!$G$6:$I$69,3,FALSE) -> 10 | K10: =VLOOKUP(A10,'volatile collection data'!$G$6:$N$69,8,FALSE) -> 4B | L10: =VLOOKUP(A10,'volatile collection data'!$G$6:$J$69,4,FALSE) -> 3.8 | M10: =VLOOKUP($A10,'volatile collection data'!$G$6:$M$69,6,FALSE) -> 8 | N10: =VLOOKUP($A10,'volatile collection data'!$G$6:$M$69,7,FALSE) -> 3.8 | O10: =VLOOKUP(A10,'volatile collection data'!$G$6:$K$69,5,FALSE) -> 0 | P10: =J10&I10 -> 10A | Q10: =IFERROR((30/H10*G10)/L10/6,0) -> 0.065882574 | R10: =K10&"_"&O10&"-"&I10&"&"&L10&"%"&N10&"@"&M10 -> 4B_0-A&3.8%3.8@8 | S10: =A10 -> 10A-4B-VCS-Loc-22 | T10: =IFERROR(IF(VLOOKUP(S10,Bad!$A:$A,1,FALSE)='RAW2'!S10,"yes","no"),"no") -> no | U10: =IFERROR(VLOOKUP(F10,compounds!$A:$B,2,FALSE),"") | V10: =VLOOKUP(B10,'volatile collection data'!$O:$P,2,FALSE) -> 24.apr.22 4
A11: 10A-4B-VCS-Loc-22 | B11: =LEFT(A11,FIND("-",A11)-1) -> 10A | C11: 8.972 | D11: =ROUND(C11,2) -> 8.97 | E11: =VLOOKUP(D11,'Peak Combiner'!$A$5:$D$4980,4,FALSE) -> 8.96 | F11: =IFERROR(VLOOKUP(D11,rt_comb!$A:$B,2,FALSE),D11) -> 8.97 | G11: 3694102 | H11: =SUMIFS($G:$G,$E:$E,18.51,'RAW2'!$A:$A,'RAW2'!A11) -> 42551864 | I11: =VLOOKUP(A11,'volatile collection data'!$G$6:$H$69,2,FALSE) -> A | J11: =VLOOKUP(A11,'volatile collection data'!$G$6:$I$69,3,FALSE) -> 10 | K11: =VLOOKUP(A11,'volatile collection data'!$G$6:$N$69,8,FALSE) -> 4B | L11: =VLOOKUP(A11,'volatile collection data'!$G$6:$J$69,4,FALSE) -> 3.8 | M11: =VLOOKUP($A11,'volatile collection data'!$G$6:$M$69,6,FALSE) -> 8 | N11: =VLOOKUP($A11,'volatile collection data'!$G$6:$M$69,7,FALSE) -> 3.8 | O11: =VLOOKUP(A11,'volatile collection data'!$G$6:$K$69,5,FALSE) -> 0 | P11: =J11&I11 -> 10A | Q11: =IFERROR((30/H11*G11)/L11/6,0) -> 0.11422909 | R11: =K11&"_"&O11&"-"&I11&"&"&L11&"%"&N11&"@"&M11 -> 4B_0-A&3.8%3.8@8 | S11: =A11 -> 10A-4B-VCS-Loc-22 | T11: =IFERROR(IF(VLOOKUP(S11,Bad!$A:$A,1,FALSE)='RAW2'!S11,"yes","no"),"no") -> no | U11: =IFERROR(VLOOKUP(F11,compounds!$A:$B,2,FALSE),"") -> bpinene | V11: =VLOOKUP(B11,'volatile collection data'!$O:$P,2,FALSE) -> 24.apr.22 4
A12: 10A-4B-VCS-Loc-22 | B12: =LEFT(A12,FIND("-",A12)-1) -> 10A | C12: 9.381 | D12: =ROUND(C12,2) -> 9.38 | E12: =VLOOKUP(D12,'Peak Combiner'!$A$5:$D$4980,4,FALSE) -> 9.38 | F12: =IFERROR(VLOOKUP(D12,rt_comb!$A:$B,2,FALSE),D12) -> 9.38 | G12: 7243660 | H12: =SUMIFS($G:$G,$E:$E,18.51,'RAW2'!$A:$A,'RAW2'!A12) -> 42551864 | I12: =VLOOKUP(A12,'volatile collection data'!$G$6:$H$69,2,FALSE) -> A | J12: =VLOOKUP(A12,'volatile collection data'!$G$6:$I$69,3,FALSE) -> 10 | K12: =VLOOKUP(A12,'volatile collection data'!$G$6:$N$69,8,FALSE) -> 4B | L12: =VLOOKUP(A12,'volatile collection data'!$G$6:$J$69,4,FALSE) -> 3.8 | M12: =VLOOKUP($A12,'volatile collection data'!$G$6:$M$69,6,FALSE) -> 8 | N12: =VLOOKUP($A12,'volatile collection data'!$G$6:$M$69,7,FALSE) -> 3.8 | O12: =VLOOKUP(A12,'volatile collection data'!$G$6:$K$69,5,FALSE) -> 0 | P12: =J12&I12 -> 10A | Q12: =IFERROR((30/H12*G12)/L12/6,0) -> 0.22398858 | R12: =K12&"_"&O12&"-"&I12&"&"&L12&"%"&N12&"@"&M12 -> 4B_0-A&3.8%3.8@8 | S12: =A12 -> 10A-4B-VCS-Loc-22 | T12: =IFERROR(IF(VLOOKUP(S12,Bad!$A:$A,1,FALSE)='RAW2'!S12,"yes","no"),"no") -> no | U12: =IFERROR(VLOOKUP(F12,compounds!$A:$B,2,FALSE),"") -> octanal | V12: =VLOOKUP(B12,'volatile collection data'!$O:$P,2,FALSE) -> 24.apr.22 4
A13: 10A-4B-VCS-Loc-22 | B13: =LEFT(A13,FIND("-",A13)-1) -> 10A | C13: 9.561 | D13: =ROUND(C13,2) -> 9.56 | E13: =VLOOKUP(D13,'Peak Combiner'!$A$5:$D$4980,4,FALSE) -> 9.53 | F13: =IFERROR(VLOOKUP(D13,rt_comb!$A:$B,2,FALSE),D13) -> 9.54 | G13: 3833068 | H13: =SUMIFS($G:$G,$E:$E,18.51,'RAW2'!$A:$A,'RAW2'!A13) -> 42551864 | I13: =VLOOKUP(A13,'volatile collection data'!$G$6:$H$69,2,FALSE) -> A | J13: =VLOOKUP(A13,'volatile collection data'!$G$6:$I$69,3,FALSE) -> 10 | K13: =VLOOKUP(A13,'volatile collection data'!$G$6:$N$69,8,FALSE) -> 4B | L13: =VLOOKUP(A13,'volatile collection data'!$G$6:$J$69,4,FALSE) -> 3.8 | M13: =VLOOKUP($A13,'volatile collection data'!$G$6:$M$69,6,FALSE) -> 8 | N13: =VLOOKUP($A13,'volatile collection data'!$G$6:$M$69,7,FALSE) -> 3.8 | O13: =VLOOKUP(A13,'volatile collection data'!$G$6:$K$69,5,FALSE) -> 0 | P13: =J13&I13 -> 10A | Q13: =IFERROR((30/H13*G13)/L13/6,0) -> 0.11852619 | R13: =K13&"_"&O13&"-"&I13&"&"&L13&"%"&N13&"@"&M13 -> 4B_0-A&3.8%3.8@8 | S13: =A13 -> 10A-4B-VCS-Loc-22 | T13: =IFERROR(IF(VLOOKUP(S13,Bad!$A:$A,1,FALSE)='RAW2'!S13,"yes","no"),"no") -> no | U13: =IFERROR(VLOOKUP(F13,compounds!$A:$B,2,FALSE),"") -> z3hex | V13: =VLOOKUP(B13,'volatile collection data'!$O:$P,2,FALSE) -> 24.apr.22 4
... A4972: 9E-25A-VCS-Loc-22 | B4972: =LEFT(A4972,FIND("-",A4972)-1) -> 9E | C4972: 40.013 | D4972: =ROUND(C4972,2) -> 40.01 | E4972: =VLOOKUP(D4972,'Peak Combiner'!$A$5:$D$4980,4,FALSE) -> 40.01 | F4972: =IFERROR(VLOOKUP(D4972,rt_comb!$A:$B,2,FALSE),D4972) -> 40.01 | G4972: 1258212 | H4972: =SUMIFS($G:$G,$E:$E,18.51,'RAW2'!$A:$A,'RAW2'!A4972) -> 24765214 | I4972: =VLOOKUP(A4972,'volatile collection data'!$G$6:$H$69,2,FALSE) -> E | J4972: =VLOOKUP(A4972,'volatile collection data'!$G$6:$I$69,3,FALSE) -> 9 | K4972: =VLOOKUP(A4972,'volatile collection data'!$G$6:$N$69,8,FALSE) -> 25A | L4972: =VLOOKUP(A4972,'volatile collection data'!$G$6:$J$69,4,FALSE) -> 6.18 | M4972: =VLOOKUP($A4972,'volatile collection data'!$G$6:$M$69,6,FALSE) -> 11 | N4972: =VLOOKUP($A4972,'volatile collection data'!$G$6:$M$69,7,FALSE) -> 6.18 | O4972: =VLOOKUP(A4972,'volatile collection data'!$G$6:$K$69,5,FALSE) -> 1 | P4972: =J4972&I4972 -> 9E | Q4972: =IFERROR((30/H4972*G4972)/L4972/6,0) -> 0.041104869 | R4972: =K4972&"_"&O4972&"-"&I4972&"&"&L4972&"%"&N4972&"@"&M4972 -> 25A_1-E&6.18%6.18@11 | S4972: =A4972 -> 9E-25A-VCS-Loc-22 | T4972: =IFERROR(IF(VLOOKUP(S4972,Bad!$A:$A,1,FALSE)='RAW2'!S4972,"yes","no"),"no") -> no | U4972: =IFERROR(VLOOKUP(F4972,compounds!$A:$B,2,FALSE),"") | V4972: =VLOOKUP(B4972,'volatile collection data'!$O:$P,2,FALSE) -> 02.may.22 25

Sheet PIVOT
B1: =IFERROR(VLOOKUP(B3,compounds!$A:$B,2,FALSE),"") | C1: =IFERROR(VLOOKUP(C3,compounds!$A:$B,2,FALSE),"") | D1: =IFERROR(VLOOKUP(D3,compounds!$A:$B,2,FALSE),"") | E1: =IFERROR(VLOOKUP(E3,compounds!$A:$B,2,FALSE),"") | F1: =IFERROR(VLOOKUP(F3,compounds!$A:$B,2,FALSE),"") | G1: =IFERROR(VLOOKUP(G3,compounds!$A:$B,2,FALSE),"") | H1: =IFERROR(VLOOKUP(H3,compounds!$A:$B,2,FALSE),"") | I1: =IFERROR(VLOOKUP(I3,compounds!$A:$B,2,FALSE),"") | ... ATS1: =IFERROR(VLOOKUP(ATS3,compounds!$A:$B,2,FALSE),"")
A2: Sum of ngghr | B2: rt.final
A3: sample | B3: 4.15 | C3: 4.16 | D3: 4.17 | E3: 4.18 | F3: 4.19 | G3: 4.33 | H3: 4.43 | I3: 4.44 | J3: 4.45 | K3: 4.47 | L3: 4.6 | M3: 4.64 | N3: 4.65 | O3: 4.7 | P3: 4.71 | Q3: 4.72 | R3: 4.73 | S3: 4.74 | T3: 4.75 | U3: 4.81 | V3: 4.82 | W3: 4.98 | X3: 4.99 | Y3: 5 | Z3: 5.01 | AA3: 5.02 | AB3: 5.03 | AC3: 5.04 | AD3: 5.1 | AE3: 5.11 | AF3: 5.12 | AG3: 5.2 | AH3: 5.21 | AI3: 5.3 | AJ3: 5.31 | AK3: 5.32 | AL3: 5.34 | AM3: 5.35 | AN3: 5.36 | AO3: 5.37 | AP3: 5.46 | AQ3: 5.56 | AR3: 5.57 | AS3: 5.58 | AT3: 5.61 | AU3: 5.74 | AV3: 5.75 | AW3: 5.76 | AX3: 5.84 | AY3: 5.85 | AZ3: 5.88 | BA3: 5.89 | BB3: 5.9 | BC3: 5.94 | BD3: 5.95 | BE3: 5.96 | BF3: 5.97 | BG3: 5.98 | BH3: 5.99 | BI3: 6.02 | BJ3: 6.04 | BK3: 6.06 | BL3: 6.12 | BM3: 6.13 | BN3: 6.14 | BO3: 6.24 | BP3: 6.25 | BQ3: 6.26 | BR3: 6.27 | BS3: 6.28 | BT3: 6.29 | BU3: 6.32 | BV3: 6.33 | BW3: 6.34 | BX3: 6.35 | BY3: 6.41 | BZ3: 6.42 | CA3: 6.43 | CB3: 6.52 | CC3: 6.64 | CD3: 6.68 | CE3: 6.69 | CF3: 6.7 | CG3: 6.71 | CH3: 6.92 | CI3: 6.93 | CJ3: 7.09 | CK3: 7.1 | CL3: 7.25 | CM3: 7.26 | CN3: 7.35 | CO3: 7.36 | CP3: 7.41 | CQ3: 7.42 | CR3: 7.47 | CS3: 7.48 | CT3: 7.5 | CU3: 7.54 | CV3: 7.55 | CW3: 7.6 | CX3: 7.72 | CY3: 7.73 | CZ3: 7.82 | DA3: 7.83 | DB3: 7.85 | DC3: 7.91 | DD3: 7.92 | DE3: 8.01 | DF3: 8.02 | DG3: 8.03 | DH3: 8.04 | DI3: 8.05 | DJ3: 8.07 | DK3: 8.08 | DL3: 8.17 | DM3: 8.21 | DN3: 8.22 | DO3: 8.25 | DP3: 8.27 | DQ3: 8.28 | DR3: 8.35 | DS3: 8.36 | DT3: 8.37 | DU3: 8.4 | DV3: 8.41 | DW3: 8.44 | DX3: 8.45 | DY3: 8.46 | DZ3: 8.47 | EA3: 8.48 | EB3: 8.49 | EC3: 8.54 | ED3: 8.55 | EE3: 8.56 | EF3: 8.62 | EG3: 8.63 | EH3: 8.64 | EI3: 8.65 | EJ3: 8.67 | EK3: 8.69 | EL3: 8.7 | EM3: 8.71 | EN3: 8.81 | EO3: 8.82 | EP3: 8.83 | EQ3: 8.84 | ER3: 8.87 | ES3: 8.88 | ET3: 8.89 | EU3: 8.91 | EV3: 8.97 | EW3: 9.01 | EX3: 9.02 | EY3: 9.03 | EZ3: 9.06 | FA3: 9.07 | FB3: 9.08 | FC3: 9.09 | FD3: 9.11 | FE3: 9.18 | FF3: 9.23 | FG3: 9.24 | FH3: 9.38 | FI3: 9.46 | FJ3: 9.47 | FK3: 9.48 | FL3: 9.49 | FM3: 9.54 | FN3: 9.65 | FO3: 9.66 | FP3: 9.67 | FQ3: 9.68 | FR3: 9.72 | FS3: 9.75 | FT3: 9.77 | FU3: 9.78 | FV3: 9.81 | FW3: 9.84 | FX3: 9.88 | FY3: 9.9 | FZ3: 9.91 | GA3: 9.99 | GB3: 10 | GC3: 10.09 | GD3: 10.1 | GE3: 10.16 | GF3: 10.17 | GG3: 10.18 | GH3: 10.19 | GI3: 10.2 | GJ3: 10.21 | GK3: 10.31 | GL3: 10.32 | GM3: 10.33 | GN3: 10.34 | GO3: 10.36 | GP3: 10.37 | GQ3: 10.4 | GR3: 10.43 | GS3: 10.46 | GT3: 10.47 | GU3: 10.48 | GV3: 10.49 | GW3: 10.53 | GX3: 10.54 | GY3: 10.57 | GZ3: 10.59 | HA3: 10.61 | HB3: 10.62 | HC3: 10.72 | HD3: 10.73 | HE3: 10.74 | HF3: 10.79 | HG3: 10.84 | HH3: 10.86 | HI3: 10.97 | HJ3: 10.99 | HK3: 11.03 | HL3: 11.04 | HM3: 11.06 | HN3: 11.07 | HO3: 11.08 | HP3: 11.13 | HQ3: 11.14 | HR3: 11.24 | HS3: 11.25 | HT3: 11.26 | HU3: 11.37 | HV3: 11.38 | HW3: 11.43 | HX3: 11.44 | HY3: 11.49 | HZ3: 11.54 | IA3: 11.55 | IB3: 11.56 | IC3: 11.57 | ID3: 11.58 | IE3: 11.59 | IF3: 11.6 | IG3: 11.63 | IH3: 11.64 | II3: 11.68 | IJ3: 11.69 | IK3: 11.76 | IL3: 11.77 | IM3: 11.79 | IN3: 11.8 | IO3: 11.81 | IP3: 11.87 | IQ3: 11.91 | IR3: 11.92 | IS3: 11.93 | IT3: 11.94 | IU3: 11.95 | IV3: 12 | IW3: 12.02 | IX3: 12.03 | IY3: 12.04 | IZ3: 12.05 | JA3: 12.09 | JB3: 12.12 | JC3: 12.13 | JD3: 12.14 | JE3: 12.18 | JF3: 12.2 | JG3: 12.21 | JH3: 12.22 | JI3: 12.27 | JJ3: 12.28 | JK3: 12.3 | JL3: 12.31 | JM3: 12.39 | JN3: 12.45 | JO3: 12.46 | JP3: 12.47 | JQ3: 12.54 | JR3: 12.63 | JS3: 12.68 | JT3: 12.73 | JU3: 12.79 | JV3: 12.8 | JW3: 12.83 | JX3: 12.84 | JY3: 12.85 | JZ3: 12.91 | KA3: 12.92 | KB3: 12.93 | KC3: 13 | KD3: 13.01 | KE3: 13.06 | KF3: 13.07 | KG3: 13.08 | KH3: 13.11 | KI3: 13.12 | KJ3: 13.14 | KK3: 13.3 | KL3: 13.35 | KM3: 13.36 | KN3: 13.38 | KO3: 13.39 | KP3: 13.52 | KQ3: 13.53 | KR3: 13.54 | KS3: 13.55 | KT3: 13.63 | KU3: 13.64 | KV3: 13.65 | KW3: 13.66 | KX3: 13.7 | KY3: 13.75 | KZ3: 13.76 | LA3: 13.78 | LB3: 13.79 | LC3: 13.82 | LD3: 13.83 | LE3: 13.9 | LF3: 13.98 | LG3: 13.99 | LH3: 14.06 | LI3: 14.08 | LJ3: 14.12 | LK3: 14.25 | LL3: 14.29 | LM3: 14.34 | LN3: 14.43 | LO3: 14.44 | LP3: 14.5 | LQ3: 14.51 | LR3: 14.58 | LS3: 14.59 | LT3: 14.6 | LU3: 14.61 | LV3: 14.62 | LW3: 14.66 | LX3: 14.67 | LY3: 14.68 | LZ3: 14.69 | MA3: 14.7 | MB3: 14.71 | MC3: 14.72 | MD3: 14.73 | ME3: 14.74 | MF3: 14.75 | MG3: 14.82 | MH3: 14.83 | MI3: 14.84 | MJ3: 14.88 | MK3: 15.02 | ML3: 15.03 | MM3: 15.04 | MN3: 15.05 | MO3: 15.08 | MP3: 15.14 | MQ3: 15.15 | MR3: 15.16 | MS3: 15.17 | MT3: 15.18 | MU3: 15.19 | MV3: 15.2 | MW3: 15.21 | MX3: 15.22 | MY3: 15.23 | MZ3: 15.24 | NA3: 15.25 | NB3: 15.26 | NC3: 15.32 | ND3: 15.33 | NE3: 15.36 | NF3: 15.37 | NG3: 15.4 | NH3: 15.41 | NI3: 15.51 | NJ3: 15.56 | NK3: 15.65 | NL3: 15.67 | NM3: 15.77 | NN3: 15.78 | NO3: 15.79 | NP3: 15.8 | NQ3: 15.87 | NR3: 15.88 | NS3: 15.89 | NT3: 15.9 | NU3: 15.92 | NV3: 15.94 | NW3: 15.95 | NX3: 15.96 | NY3: 16 | NZ3: 16.01 | OA3: 16.02 | OB3: 16.03 | OC3: 16.04 | OD3: 16.05 | OE3: 16.07 | OF3: 16.09 | OG3: 16.14 | OH3: 16.15 | OI3: 16.16 | OJ3: 16.17 | OK3: 16.18 | OL3: 16.21 | OM3: 16.23 | ON3: 16.25 | OO3: 16.26 | OP3: 16.33 | OQ3: 16.34 | OR3: 16.35 | OS3: 16.37 | OT3: 16.43 | OU3: 16.44 | OV3: 16.45 | OW3: 16.46 | OX3: 16.47 | OY3: 16.53 | OZ3: 16.54 | PA3: 16.6 | PB3: 16.61 | PC3: 16.63 | PD3: 16.64 | PE3: 16.65 | PF3: 16.72 | PG3: 16.73 | PH3: 16.77 | PI3: 16.78 | PJ3: 16.79 | PK3: 16.8 | PL3: 16.85 | PM3: 16.86 | PN3: 16.89 | PO3: 16.9 | PP3: 16.91 | PQ3: 17.02 | PR3: 17.03 | PS3: 17.04 | PT3: 17.07 | PU3: 17.16 | PV3: 17.17 | PW3: 17.18 | PX3: 17.19 | PY3: 17.2 | PZ3: 17.21 | QA3: 17.22 | QB3: 17.23 | QC3: 17.24 | QD3: 17.25 | QE3: 17.29 | QF3: 17.3 | QG3: 17.43 | QH3: 17.44 | QI3: 17.45 | QJ3: 17.46 | QK3: 17.49 | QL3: 17.57 | QM3: 17.58 | QN3: 17.59 | QO3: 17.69 | QP3: 17.74 | QQ3: 17.75 | QR3: 17.79 | QS3: 17.82 | QT3: 17.83 | QU3: 17.84 | QV3: 17.87 | QW3: 17.88 | QX3: 17.89 | QY3: 17.9 | QZ3: 17.92 | RA3: 17.93 | RB3: 17.98 | RC3: 17.99 | RD3: 18.01 | RE3: 18.02 | RF3: 18.03 | RG3: 18.04 | RH3: 18.06 | RI3: 18.07 | RJ3: 18.08 | RK3: 18.09 | RL3: 18.1 | RM3: 18.14 | RN3: 18.15 | RO3: 18.21 | RP3: 18.22 | RQ3: 18.29 | RR3: 18.3 | RS3: 18.39 | RT3: 18.4 | RU3: 18.41 | RV3: 18.42 | RW3: 18.43 | RX3: 18.44 | RY3: 18.52 | RZ3: 18.6 | SA3: 18.61 | SB3: 18.66 | SC3: 18.76 | SD3: 18.77 | SE3: 18.78 | SF3: 18.89 | SG3: 18.9 | SH3: 18.96 | SI3: 18.97 | SJ3: 19.01 | SK3: 19.02 | SL3: 19.03 | SM3: 19.09 | SN3: 19.1 | SO3: 19.11 | SP3: 19.12 | SQ3: 19.16 | SR3: 19.17 | SS3: 19.19 | ST3: 19.22 | SU3: 19.23 | SV3: 19.29 | SW3: 19.3 | SX3: 19.31 | SY3: 19.43 | SZ3: 19.44 | TA3: 19.54 | TB3: 19.55 | TC3: 19.56 | TD3: 19.59 | TE3: 19.7 | TF3: 19.71 | TG3: 19.75 | TH3: 19.76 | TI3: 19.77 | TJ3: 19.78 | TK3: 19.82 | TL3: 19.91 | TM3: 19.92 | TN3: 19.93 | TO3: 19.98 | TP3: 20.05 | TQ3: 20.11 | TR3: 20.12 | TS3: 20.13 | TT3: 20.14 | TU3: 20.21 | TV3: 20.22 | TW3: 20.27 | TX3: 20.31 | TY3: 20.32 | TZ3: 20.33 | UA3: 20.45 | UB3: 20.47 | UC3: 20.5 | UD3: 20.51 | UE3: 20.55 | UF3: 20.57 | UG3: 20.58 | UH3: 20.63 | UI3: 20.64 | UJ3: 20.69 | UK3: 20.71 | UL3: 20.72 | UM3: 20.73 | UN3: 20.85 | UO3: 20.95 | UP3: 20.96 | UQ3: 20.98 | UR3: 21.06 | US3: 21.07 | UT3: 21.08 | UU3: 21.09 | UV3: 21.11 | UW3: 21.22 | UX3: 21.23 | UY3: 21.27 | UZ3: 21.28 | VA3: 21.29 | VB3: 21.32 | VC3: 21.33 | VD3: 21.41 | VE3: 21.42 | VF3: 21.44 | VG3: 21.45 | VH3: 21.5 | VI3: 21.51 | VJ3: 21.52 | VK3: 21.56 | VL3: 21.57 | VM3: 21.58 | VN3: 21.6 | VO3: 21.61 | VP3: 21.62 | VQ3: 21.66 | VR3: 21.7 | VS3: 21.71 | VT3: 21.74 | VU3: 21.75 | VV3: 21.76 | VW3: 21.77 | VX3: 21.78 | VY3: 21.79 | VZ3: 21.84 | WA3: 21.85 | WB3: 21.86 | WC3: 21.89 | WD3: 21.9 | WE3: 21.93 | WF3: 21.95 | WG3: 22.06 | WH3: 22.07 | WI3: 22.1 | WJ3: 22.12 | WK3: 22.18 | WL3: 22.23 | WM3: 22.25 | WN3: 22.26 | WO3: 22.27 | WP3: 22.29 | WQ3: 22.32 | WR3: 22.36 | WS3: 22.37 | WT3: 22.39 | WU3: 22.4 | WV3: 22.41 | WW3: 22.49 | WX3: 22.5 | WY3: 22.52 | WZ3: 22.53 | XA3: 22.63 | XB3: 22.64 | XC3: 22.7 | XD3: 22.71 | XE3: 22.72 | XF3: 22.74 | XG3: 22.75 | XH3: 22.76 | XI3: 22.77 | XJ3: 22.8 | XK3: 22.81 | XL3: 22.82 | XM3: 22.83 | XN3: 22.84 | XO3: 22.86 | XP3: 22.87 | XQ3: 22.88 | XR3: 22.89 | XS3: 22.93 | XT3: 22.97 | XU3: 22.98 | XV3: 22.99 | XW3: 23 | XX3: 23.01 | XY3: 23.02 | XZ3: 23.03 | YA3: 23.04 | YB3: 23.05 | YC3: 23.06 | YD3: 23.13 | YE3: 23.14 | YF3: 23.15 | YG3: 23.16 | YH3: 23.21 | YI3: 23.22 | YJ3: 23.23 | YK3: 23.24 | YL3: 23.25 | YM3: 23.26 | YN3: 23.27 | YO3: 23.32 | YP3: 23.33 | YQ3: 23.34 | YR3: 23.38 | YS3: 23.45 | YT3: 23.46 | YU3: 23.47 | YV3: 23.48 | YW3: 23.54 | YX3: 23.55 | YY3: 23.56 | YZ3: 23.57 | ZA3: 23.58 | ZB3: 23.59 | ZC3: 23.61 | ZD3: 23.62 | ZE3: 23.63 | ZF3: 23.64 | ZG3: 23.66 | ZH3: 23.67 | ZI3: 23.68 | ZJ3: 23.69 | ZK3: 23.7 | ZL3: 23.75 | ZM3: 23.76 | ZN3: 23.78 | ZO3: 23.79 | ZP3: 23.86 | ZQ3: 23.89 | ZR3: 23.9 | ZS3: 23.97 | ZT3: 23.98 | ZU3: 23.99 | ZV3: 24 | ZW3: 24.03 | ZX3: 24.04 | ZY3: 24.05 | ZZ3: 24.06 | AAA3: 24.09 | AAB3: 24.1 | AAC3: 24.16 | AAD3: 24.23 | AAE3: 24.24 | AAF3: 24.25 | AAG3: 24.33 | AAH3: 24.34 | AAI3: 24.41 | AAJ3: 24.44 | AAK3: 24.45 | AAL3: 24.46 | AAM3: 24.54 | AAN3: 24.55 | AAO3: 24.62 | AAP3: 24.69 | AAQ3: 24.7 | AAR3: 24.71 | AAS3: 24.81 | AAT3: 24.82 | AAU3: 24.83 | AAV3: 24.85 | AAW3: 24.86 | AAX3: 24.91 | AAY3: 24.93 | AAZ3: 24.94 | ABA3: 24.95 | ABB3: 24.98 | ABC3: 24.99 | ABD3: 25.02 | ABE3: 25.03 | ABF3: 25.07 | ABG3: 25.09 | ABH3: 25.11 | ABI3: 25.12 | ABJ3: 25.13 | ABK3: 25.15 | ABL3: 25.16 | ABM3: 25.17 | ABN3: 25.21 | ABO3: 25.22 | ABP3: 25.23 | ABQ3: 25.28 | ABR3: 25.29 | ABS3: 25.3 | ABT3: 25.36 | ABU3: 25.45 | ABV3: 25.46 | ABW3: 25.49 | ABX3: 25.5 | ABY3: 25.51 | ABZ3: 25.52 | ACA3: 25.55 | ACB3: 25.62 | ACC3: 25.63 | ACD3: 25.64 | ACE3: 25.67 | ACF3: 25.68 | ACG3: 25.69 | ACH3: 25.7 | ACI3: 25.75 | ACJ3: 25.76 | ACK3: 25.77 | ACL3: 25.79 | ACM3: 25.8 | ACN3: 25.82 | ACO3: 25.83 | ACP3: 25.88 | ACQ3: 25.89 | ACR3: 25.9 | ACS3: 25.96 | ACT3: 25.97 | ACU3: 26.04 | ACV3: 26.09 | ACW3: 26.1 | ACX3: 26.13 | ACY3: 26.18 | ACZ3: 26.2 | ADA3: 26.21 | ADB3: 26.32 | ADC3: 26.36 | ADD3: 26.37 | ADE3: 26.4 | ADF3: 26.41 | ADG3: 26.46 | ADH3: 26.47 | ADI3: 26.48 | ADJ3: 26.49 | ADK3: 26.51 | ADL3: 26.52 | ADM3: 26.6 | ADN3: 26.61 | ADO3: 26.62 | ADP3: 26.63 | ADQ3: 26.64 | ADR3: 26.65 | ADS3: 26.66 | ADT3: 26.67 | ADU3: 26.68 | ADV3: 26.75 | ADW3: 26.76 | ADX3: 26.77 | ADY3: 26.78 | ADZ3: 26.85 | AEA3: 26.9 | AEB3: 26.91 | AEC3: 26.92 | AED3: 26.93 | AEE3: 26.94 | AEF3: 26.98 | AEG3: 26.99 | AEH3: 27.07 | AEI3: 27.11 | AEJ3: 27.16 | AEK3: 27.17 | AEL3: 27.19 | AEM3: 27.29 | AEN3: 27.3 | AEO3: 27.31 | AEP3: 27.32 | AEQ3: 27.33 | AER3: 27.36 | AES3: 27.37 | AET3: 27.38 | AEU3: 27.4 | AEV3: 27.41 | AEW3: 27.45 | AEX3: 27.46 | AEY3: 27.47 | AEZ3: 27.61 | AFA3: 27.62 | AFB3: 27.69 | AFC3: 27.7 | AFD3: 27.72 | AFE3: 27.73 | AFF3: 27.75 | AFG3: 27.76 | AFH3: 27.9 | AFI3: 27.91 | AFJ3: 27.92 | AFK3: 27.93 | AFL3: 28 | AFM3: 28.01 | AFN3: 28.02 | AFO3: 28.03 | AFP3: 28.04 | AFQ3: 28.13 | AFR3: 28.14 | AFS3: 28.15 | AFT3: 28.26 | AFU3: 28.28 | AFV3: 28.29 | AFW3: 28.4 | AFX3: 28.41 | AFY3: 28.45 | AFZ3: 28.46 | AGA3: 28.47 | AGB3: 28.51 | AGC3: 28.53 | AGD3: 28.55 | AGE3: 28.56 | AGF3: 28.69 | AGG3: 28.7 | AGH3: 28.71 | AGI3: 28.84 | AGJ3: 28.85 | AGK3: 28.92 | AGL3: 28.93 | AGM3: 28.94 | AGN3: 29 | AGO3: 29.01 | AGP3: 29.03 | AGQ3: 29.04 | AGR3: 29.13 | AGS3: 29.14 | AGT3: 29.15 | AGU3: 29.18 | AGV3: 29.19 | AGW3: 29.25 | AGX3: 29.26 | AGY3: 29.27 | AGZ3: 29.32 | AHA3: 29.41 | AHB3: 29.44 | AHC3: 29.45 | AHD3: 29.48 | AHE3: 29.53 | AHF3: 29.54 | AHG3: 29.6 | AHH3: 29.62 | AHI3: 29.74 | AHJ3: 29.75 | AHK3: 29.76 | AHL3: 29.89 | AHM3: 29.9 | AHN3: 29.92 | AHO3: 29.94 | AHP3: 29.95 | AHQ3: 30.02 | AHR3: 30.03 | AHS3: 30.04 | AHT3: 30.08 | AHU3: 30.09 | AHV3: 30.16 | AHW3: 30.17 | AHX3: 30.2 | AHY3: 30.26 | AHZ3: 30.3 | AIA3: 30.37 | AIB3: 30.38 | AIC3: 30.4 | AID3: 30.46 | AIE3: 30.47 | AIF3: 30.48 | AIG3: 30.59 | AIH3: 30.6 | AII3: 30.61 | AIJ3: 30.67 | AIK3: 30.73 | AIL3: 30.74 | AIM3: 30.75 | AIN3: 30.76 | AIO3: 30.9 | AIP3: 30.91 | AIQ3: 30.94 | AIR3: 30.95 | AIS3: 30.96 | AIT3: 30.97 | AIU3: 30.98 | AIV3: 30.99 | AIW3: 31.07 | AIX3: 31.08 | AIY3: 31.14 | AIZ3: 31.15 | AJA3: 31.24 | AJB3: 31.25 | AJC3: 31.26 | AJD3: 31.29 | AJE3: 31.3 | AJF3: 31.4 | AJG3: 31.41 | AJH3: 31.42 | AJI3: 31.43 | AJJ3: 31.65 | AJK3: 31.66 | AJL3: 31.67 | AJM3: 31.73 | AJN3: 31.74 | AJO3: 31.75 | AJP3: 31.76 | AJQ3: 31.77 | AJR3: 31.78 | AJS3: 31.81 | AJT3: 31.89 | AJU3: 32 | AJV3: 32.04 | AJW3: 32.05 | AJX3: 32.23 | AJY3: 32.24 | AJZ3: 32.27 | AKA3: 32.28 | AKB3: 32.38 | AKC3: 32.39 | AKD3: 32.57 | AKE3: 32.58 | AKF3: 32.59 | AKG3: 32.7 | AKH3: 32.71 | AKI3: 32.79 | AKJ3: 32.96 | AKK3: 33.01 | AKL3: 33.11 | AKM3: 33.12 | AKN3: 33.14 | AKO3: 33.23 | AKP3: 33.24 | AKQ3: 33.25 | AKR3: 33.31 | AKS3: 33.32 | AKT3: 33.39 | AKU3: 33.76 | AKV3: 33.79 | AKW3: 33.85 | AKX3: 33.97 | AKY3: 33.98 | AKZ3: 33.99 | ALA3: 34.06 | ALB3: 34.07 | ALC3: 34.19 | ALD3: 34.21 | ALE3: 34.22 | ALF3: 34.4 | ALG3: 34.41 | ALH3: 34.42 | ALI3: 34.43 | ALJ3: 34.58 | ALK3: 34.86 | ALL3: 34.87 | ALM3: 34.93 | ALN3: 34.94 | ALO3: 34.95 | ALP3: 34.97 | ALQ3: 34.98 | ALR3: 35 | ALS3: 35.02 | ALT3: 35.13 | ALU3: 35.16 | ALV3: 35.17 | ALW3: 35.18 | ALX3: 35.19 | ALY3: 35.22 | ALZ3: 35.23 | AMA3: 35.24 | AMB3: 35.28 | AMC3: 35.29 | AMD3: 35.3 | AME3: 35.31 | AMF3: 35.4 | AMG3: 35.42 | AMH3: 35.43 | AMI3: 35.44 | AMJ3: 35.48 | AMK3: 35.63 | AML3: 35.64 | AMM3: 35.66 | AMN3: 35.67 | AMO3: 35.79 | AMP3: 35.8 | AMQ3: 35.83 | AMR3: 35.84 | AMS3: 35.85 | AMT3: 35.89 | AMU3: 35.9 | AMV3: 35.91 | AMW3: 35.96 | AMX3: 35.99 | AMY3: 36 | AMZ3: 36.03 | ANA3: 36.11 | ANB3: 36.12 | ANC3: 36.16 | AND3: 36.17 | ANE3: 36.2 | ANF3: 36.27 | ANG3: 36.28 | ANH3: 36.29 | ANI3: 36.34 | ANJ3: 36.35 | ANK3: 36.41 | ANL3: 36.54 | ANM3: 36.55 | ANN3: 36.58 | ANO3: 36.59 | ANP3: 36.6 | ANQ3: 36.62 | ANR3: 36.63 | ANS3: 36.64 | ANT3: 36.65 | ANU3: 36.66 | ANV3: 36.67 | ANW3: 36.68 | ANX3: 36.72 | ANY3: 36.73 | ANZ3: 36.74 | AOA3: 36.75 | AOB3: 36.76 | AOC3: 36.77 | AOD3: 36.78 | AOE3: 36.79 | AOF3: 36.8 | AOG3: 36.84 | AOH3: 36.87 | AOI3: 36.89 | AOJ3: 36.96 | AOK3: 36.97 | AOL3: 37 | AOM3: 37.01 | AON3: 37.02 | AOO3: 37.03 | AOP3: 37.04 | AOQ3: 37.06 | AOR3: 37.08 | AOS3: 37.09 | AOT3: 37.1 | AOU3: 37.11 | AOV3: 37.12 | AOW3: 37.13 | AOX3: 37.14 | AOY3: 37.19 | AOZ3: 37.2 | APA3: 37.21 | APB3: 37.23 | APC3: 37.24 | APD3: 37.25 | APE3: 37.29 | APF3: 37.3 | APG3: 37.31 | APH3: 37.32 | API3: 37.34 | APJ3: 37.37 | APK3: 37.38 | APL3: 37.47 | APM3: 37.53 | APN3: 37.54 | APO3: 37.58 | APP3: 37.59 | APQ3: 37.6 | APR3: 37.63 | APS3: 37.64 | APT3: 37.65 | APU3: 37.66 | APV3: 37.67 | APW3: 37.68 | APX3: 37.69 | APY3: 37.7 | APZ3: 37.71 | AQA3: 37.72 | AQB3: 37.75 | AQC3: 37.76 | AQD3: 37.77 | AQE3: 37.78 | AQF3: 37.79 | AQG3: 37.8 | AQH3: 37.81 | AQI3: 37.85 | AQJ3: 37.9 | AQK3: 37.93 | AQL3: 37.98 | AQM3: 37.99 | AQN3: 38 | AQO3: 38.02 | AQP3: 38.04 | AQQ3: 38.05 | AQR3: 38.06 | AQS3: 38.12 | AQT3: 38.14 | AQU3: 38.16 | AQV3: 38.17 | AQW3: 38.19 | AQX3: 38.2 | AQY3: 38.21 | AQZ3: 38.3 | ARA3: 38.31 | ARB3: 38.32 | ARC3: 38.33 | ARD3: 38.35 | ARE3: 38.4 | ARF3: 38.41 | ARG3: 38.42 | ARH3: 38.43 | ARI3: 38.44 | ARJ3: 38.45 | ARK3: 38.46 | ARL3: 38.47 | ARM3: 38.48 | ARN3: 38.62 | ARO3: 38.66 | ARP3: 38.68 | ARQ3: 38.71 | ARR3: 38.72 | ARS3: 38.73 | ART3: 38.74 | ARU3: 38.82 | ARV3: 38.83 | ARW3: 38.92 | ARX3: 38.94 | ARY3: 39.05 | ARZ3: 39.1 | ASA3: 39.12 | ASB3: 39.22 | ASC3: 39.27 | ASD3: 39.32 | ASE3: 39.4 | ASF3: 39.41 | ASG3: 39.44 | ASH3: 39.45 | ASI3: 39.53 | ASJ3: 39.54 | ASK3: 39.55 | ASL3: 39.56 | ASM3: 39.58 | ASN3: 39.59 | ASO3: 39.63 | ASP3: 39.67 | ASQ3: 39.68 | ASR3: 39.69 | ASS3: 39.75 | AST3: 39.76 | ASU3: 39.77 | ASV3: 39.87 | ASW3: 39.94 | ASX3: 39.95 | ASY3: 39.96 | ASZ3: 40 | ATA3: 40.01 | ATB3: 40.02 | ATC3: 40.1 | ATD3: 40.13 | ATE3: 40.17 | ATF3: (blank) | ATG3: Grand Total
A4: 10A | D4: 0.044673319 | K4: 0.034472095 | S4: 0.037300515 | BT4: 0.027950923 | BW4: 0.034762254 | EV4: 0.089262503 | FH4: 0.4402091 | FM4: 0.054580989 | GI4: 0.099278516 | JM4: 0.17253849 | JQ4: 0.487323 | KB4: 0.073268187 | LK4: 0.05135383 | NH4: 0.078199393 | NJ4: 0.24274279 | NP4: 0.061592945 | OW4: 0.076562844 | RP4: 0.085449832 | RY4: 1.1210762 | TP4: 0.055630022 | VC4: 0.40601647 | YQ4: 0.061541813 | ABR4: 0.19054402 | ACC4: 0.093093577 | ACG4: 0.048782668 | AIU4: 0.040490428 | AJQ4: 0.13437435 | ALL4: 0.03391096 | ALO4: 0.055834485 | AND4: 0.061848982 | ANR4: 0.36649569 | APF4: 0.074167319 | APX4: -0.0061279665 | AQM4: 0.44230258 | ARI4: 0.27567025 | ATG4: 5.6471734
A5: 10B | D5: 0.23714075 | G5: 0.014045284 | I5: 0.018462553 | T5: 0.012415264 | AK5: 0.022630128 | AQ5: 0.019289478 | AY5: 0.34357141 | BA5: 0.4569742 | BL5: 0.082297964 | BO5: 0.11867464 | CE5: 0.022255205 | CJ5: 0.071944439 | CM5: 0.0082858682 | CN5: 0.017837808 | CP5: 0.011519044 | CU5: 0.015433096 | CZ5: 0.037566702 | DC5: 0.050374969 | DF5: 0.071843377 | DM5: 0.03462825 | DP5: 0.036882196 | DS5: 0.057713825 | DY5: 0.064481469 | EC5: 0.045128643 | EK5: 0.11162179 | ET5: 1.5104295 | FF5: 0.36618888 | FH5: 0.97247377 | FM5: 0.42155653 | FO5: 0.19930998 | FV5: 0.35704725 | GA5: 0.70187294 | GC5: 0.53857355 | GE5: 0.39887165 | GL5: 0.28080468 | GU5: 0.19111184 | GW5: 0.21133641 | HA5: 0.25155478 | HD5: 0.71548107 | HN5: 0.34254081 | HP5: 0.36818657 | HR5: 0.28741893 | HU5: 0.38203555 | HW5: 0.40768282 | IE5: 0.8698069 | II5: 0.36226441 | IN5: 0.82959863 | IQ5: 1.4586346 | IW5: 1.1256288 | JB5: 0.61501177 | JL5: 0.99217274 | JM5: 0.97743775 | JN5: 0.43077298 | JQ5: 2.9493184 | JT5: 0.4209444 | JX5: 0.8988743 | JZ5: 0.46075787 | KC5: 0.49858904 | KH5: 0.99303164 | KK5: 0.43342691 | KL5: 0.39560877 | KQ5: 0.66920356 | KV5: 0.26389483 | LC5: 0.25314517 | LE5: 0.26402588 | LF5: 0.18689496 | LI5: 0.16261439 | LK5: 0.98725388 | LQ5: 0.081634786 | LT5: 0.2608152 | MD5: 0.37171553 | MH5: 0.23509261 | MJ5: 0.249132 | MM5: 0.33184991 | MU5: 0.84743644 | NE5: 0.56513594 | NJ5: 1.4130897 | NM5: 0.30100182 | NS5: 0.1710478 | NV5: 0.1175083 | OH5: 0.17998077 | OM5: 0.10410124 | OT5: 0.31753289 | OZ5: 0.14059148 | PF5: 0.31889844 | PO5: 0.28151015 | PS5: 0.16447152 | PW5: 0.34171544 | QF5: 0.12840692 | QH5: 0.50834035 | QN5: 0.15281541 | QO5: 0.51208008 | QT5: 0.25633049 | QZ5: 0.27728561 | RG5: 0.43556664 | RM5: 0.3873559 | RO5: 0.41581446 | RQ5: 0.19078277 | RS5: 0.62451299 | RY5: 0.96525097 | RZ5: 0.54724188 | SC5: 3.096794 | SF5: 4.7956027 | SH5: 0.9228503 | SO5: 5.3465702 | SU5: 0.30111028 | SW5: 0.41220253 | SZ5: 0.41946567 | TB5: 0.79477005 | TI5: 0.8252784 | TO5: 0.57592848 | TP5: 1.2630617 | TS5: 0.42727431 | TX5: 1.3275817 | UC5: 0.51762757 | UF5: 0.17376773 | UH5: 0.42817948 | UL5: 0.44060198 | UN5: 1.3834034 | UP5: 1.9985879 | US5: 1.0169272 | UW5: 0.50726472 | VC5: 0.43920292 | VD5: 0.97409668 | VJ5: 0.21571598 | VN5: 0.81400751 | VV5: 0.72883242 | WA5: 0.3057199 | WC5: 0.4056103 | WH5: 1.074567 | WK5: 0.46969615 | WN5: 0.3424353 | WQ5: 0.24469359 | WT5: 0.4851824 | WW5: 0.68205748 | XA5: 0.8441202 | XF5: 0.57778167 | XQ5: 0.62361604 | XU5: 0.2467679 | XX5: 0.3567787 | YF5: 0.51302096 | YM5: 0.31745875 | YP5: 0.51870109 | YU5: 0.47884228 | YZ5: 0.19735921 | ZG5: 0.54634438 | ZO5: 0.210356 | ZQ5: 0.39008534 | ZY5: 0.64853858 | AAC5: 0.19841631 | AAE5: 0.5777881 | AAG5: 0.17643081 | AAK5: 0.65413098 | AAM5: 0.25322295 | AAO5: 0.20715997 | AAQ5: 0.23565433 | AAS5: 0.43865592 | AAX5: 0.11967545 | ABC5: 0.25197839 | ABF5: 0.16247701 | ABL5: 0.31380784 | ABV5: 0.67646397 | ACA5: 0.46436668 | ACB5: 0.29245158 | ACE5: 0.45770988 | ACN5: 0.60763205 | ACS5: 0.22188856 | ACX5: 0.40181525 | ACY5: 0.40382348 | ADE5: 0.42616362 | ADH5: 0.33115002 | ADT5: 0.77641949 | ADW5: 0.43423886 | AED5: 0.63631256 | AEF5: 0.34151302 | AEH5: 0.45442142 | AEK5: 0.55848979 | AEP5: 0.39133836 | AEU5: 0.38334052 | AEW5: 0.40886064 | AEZ5: 0.56782784 | AFB5: 0.45137445 | AFF5: 0.28061352 | AFI5: 0.75899597 | AFM5: 0.69383367 | AFS5: 0.43098655 | AFT5: 0.37822028 | AFW5: 0.28498351 | AFZ5: 0.16362005 | AGD5: 0.41136333 | AGG5: 0.52336744 | AGJ5: 0.17621108 | AGM5: 0.33751445 | AGN5: 0.34371334 | AGS5: 0.26309298 | AGX5: 0.15541103 | AGZ5: 0.26399125 | AHC5: 0.24129442 | AHE5: 0.18896406 | AHG5: 0.28805296 | AHJ5: 0.19189726 | AHM5: 0.1705559 | AHO5: 0.13174728 | AHQ5: 0.22446115 | AHW5: 0.18439324 | AIE5: 0.16082857 | AIH5: 0.12923762 | AIK5: 0.12285733 | AIO5: 0.31748241 | AIY5: 0.058815473 | AJB5: 0.046161136 | AJD5: 0.039844081 | AJG5: 0.20550174 | AJO5: 0.19815404 | AJT5: 0.034294373 | AKC5: 0.048577586 | AKL5: 0.041834632 | AKS5: 0.025323603 | ALK5: 0.010140413 | ALN5: 0.038450153 | AMM5: 0.011153429 | AND5: 0.010648023 | ANP5: 0.02087591 | ANU5: 0.012526424 | ANZ5: 0.022853621 | AOO5: 0.0084747705 | APC5: 0.01726613 | APF5: 0.018623941 | APK5: 0.016187392 | APW5: 0.027741988 | AQC5: 0.01038354 | AQN5: 0.21309504 | ARL5: 0.063494146 | ARU5: 0.025761522 | ASS5: 0.027901709 | ATG5: 103.55767
A6: 11A | E6: 0.051829155 | R6: 0.069055287 | AB6: 0.039385612 | BW6: 0.070325443 | EI6: 0.086428104 | EV6: 0.18592609 | FH6: 0.20207639 | FM6: 0.13431292 | GI6: 0.1145437 | JM6: 0.44189831 | JQ6: 0.60612368 | KA6: 0.11144487 | LK6: 0.099183902 | NJ6: 0.329376 | NN6: 0.079881356 | RJ6: 0.06444795 | RY6: 1.3477089 | SB6: 0.076156835 | TC6: 0.25867999 | TG6: 0.084720495 | TP6: 0.05814959 | UT6: 0.10589929 | WG6: 0.084433149 | WR6: 0.064725025 | YQ6: 0.067786077 | ABL6: 0.13334215 | ACF6: 0.09509642 | AIR6: 0.22612026 | AJG6: 0.081212192 | AJK6: 0.57864422 | AJM6: 0.7192934 | ALN6: 0.093079861 | AMN6: 0.065710904 | AND6: 0.066525307 | ANL6: -0.008141082 | ANO6: 0.067837017 | ANU6: 0.063831466 | APF6: 0.062604814 | APK6: 0.073079551 | APZ6: 0.20068139 | AQM6: 0.52706216 | AQQ6: 0.25095316 | ARK6: 0.15089807 | ARU6: 0.12090008 | AST6: 0.12528058 | ATG6: 8.52851
A7: 11B | D7: 0.023619864 | FH7: 0.46921841 | JQ7: 1.1930375 | KB7: 0.12477426 | NJ7: 0.555614 | OW7: 0.17656843 | RY7: 2.1097046 | VC7: 0.27418028 | AJO7: 1.0977921 | AJW7: 0.10654551 | ALD7: 2.4338869 | ALN7: 0.19762354 | AND7: 0.12837619 | ANL7: 0.030304808 | ANQ7: 0.22477756 | AOW7: 0.3739906 | AOY7: 0.071306107 | APF7: 0.53277917 | APP7: 0.27234527 | APV7: 1.250146 | AQM7: 1.6102295 | ARK7: 1.0280108 | ASK7: 0.24601468 | ATG7: 14.530846
A8: 12A | E8: 0.15163653 | Y8: 0.65642139 | AD8: 0.13877311 | AK8: 0.097426437 | AR8: 0.092760705 | BD8: 0.033938393 | BQ8: 0.094428358 | BV8: 0.16269078 | BY8: 0.12810148 | CJ8: 0.11646232 | DA8: 0.062609057 | DD8: 0.07611441 | DF8: 0.21773292 | DQ8: 0.082573878 | DT8: 0.10249694 | EL8: 0.29539477 | EN8: 0.11605124 | EU8: 0.11642334 | EV8: 0.23662129 | FE8: 0.14434702 | FF8: 0.3139274 | FH8: 1.0867208 | FL8: 0.55302814 | FP8: 0.21592074 | FV8: 0.97086569 | GB8: 1.2156891 | GC8: 0.58488545 | GF8: 0.41751676 | GL8: 0.74497751 | GV8: 0.20049939 | GX8: 0.20812605 | HA8: 0.249216 | HD8: 0.2621033 | HF8: 0.62566531 | HN8: 0.24720412 | HP8: 0.3253035 | HR8: 0.25836562 | HU8: 0.3118817 | HX8: 0.30016173 | IF8: 0.70409495 | II8: 0.27978807 | IK8: 0.68835254 | IR8: 1.0248333 | IW8: 1.3179149 | JL8: 0.94232243 | JM8: 1.4638515 | JQ8: 2.4305653 | JX8: 0.47501444 | JZ8: 1.5347532 | KH8: 0.6107846 | KK8: 0.27909858 | KL8: 0.26603272 | KQ8: 0.43564125 | LE8: 0.11993078 | LF8: 0.088610401 | LK8: 0.2809239 | LS8: 0.12915793 | MC8: 0.3950602 | MH8: 0.17815025 | MJ8: 0.18564061 | MO8: 0.17952104 | MU8: 1.073267 | NE8: 0.48272828 | NJ8: 0.86411958 | NM8: 0.12616167 | NV8: 0.068816089 | OB8: 0.12359079 | OU8: 0.94252325 | PF8: 0.14885137 | PI8: 0.10553867 | PX8: 0.15857477 | QG8: 0.35382337 | QN8: 0.063115516 | QO8: 0.22375873 | QT8: 0.13262574 | RN8: 0.31606765 | RO8: 0.24793962 | RS8: 0.25874465 | RY8: 1.3927577 | SC8: 1.6714902 | SF8: 2.6813102 | SH8: 0.43312357 | SO8: 3.0579238 | SZ8: 0.13185807 | TH8: 0.24806315 | TO8: 0.21670697 | TP8: 0.58621843 | TS8: 0.12934387 | TY8: 0.45185586 | UD8: 0.18235982 | UI8: 0.12768588 | UL8: 0.18867944 | UN8: 0.49281899 | UO8: 0.85856984 | US8: 0.63692073 | VD8: 0.35947561 | VN8: 0.36965324 | VT8: 0.26621108 | VZ8: 0.10155803 | WC8: 0.19906546 | WH8: 0.33232193 | WS8: 0.2309706 | WW8: 0.21119786 | XA8: 0.24254179 | XE8: 0.51964813 | XQ8: 0.18099889 | YE8: 0.16332371 | YP8: 0.18408624 | YT8: 0.11101468 | ZH8: 0.28141625 | ZQ8: 0.16870561 | ZY8: 0.16633988 | AAE8: 0.085788359 | AAK8: 0.097826686 | AAS8: 0.050059593 | AAY8: 0.081646601 | ABO8: 0.13427499 | ABU8: 0.097618171 | ACB8: 0.30930648 | ADT8: 0.10898282 | AEP8: 0.091796813 | AEZ8: 0.032618677 | AFI8: 0.11643286 | AFO8: 0.089276117 | AFQ8: 0.099390372 | AHB8: 0.58069981 | AHR8: 0.050143262 | AIR8: 0.09290612 | AJG8: 0.061345404 | AJN8: 0.37765145 | ALD8: 2.7219114 | ALJ8: 0.034641149 | ALN8: 0.072642195 | ANC8: 0.04393364 | ANO8: 0.095370559 | ANZ8: 0.053173432 | AOO8: 0.10280486 | APD8: 0.054262402 | APF8: 0.085627401 | AQA8: 0.13402541 | AQM8: 0.68143414 | ARJ8: 0.11769821 | ATG8: 56.246857
A9: 13A | D9: -0.04409312 | I9: 0.067420506 | P9: 0.23698589 | V9: 0.062167889 | AA9: 0.13797406 | BR9: 0.019193249 | CK9: 0.053576966 | EV9: 0.1472829 | FH9: 0.16335543 | FM9: 0.11941539 | GD9: 0.5407764 | GH9: 0.20156038 | GR9: 0.17215031 | HZ9: 0.065111035 | JM9: 0.039762916 | JQ9: 0.34218702 | JS9: 0.030455085 | JY9: 0.029250644 | KA9: 0.11888611 | LK9: 0.033973225 | MZ9: 0.088895973 | NJ9: 0.34583182 | NN9: 0.068515579 | OD9: 0.087383588 | OV9: 0.062407332 | RU9: 0.042126485 | RY9: 1.0548523 | SD9: 0.044664131 | TC9: 0.13837792 | TP9: 0.025503592 | UT9: 0.04919793 | VB9: 1.5048436 | WK9: 0.078111985 | YP9: 0.035334448 | YX9: 0.11693405 | ABR9: 0.24279705 | ABU9: 0.067656211 | ACF9: 0.09376767 | ADQ9: 0.065189385 | AFJ9: 0.029989268 | AGB9: 0.22114655 | AGP9: 0.10666187 | AHR9: 0.05886794 | AHY9: 0.090528475 | AIG9: 0.090180019 | AIS9: 0.10741768 | AJB9: 0.049012067 | AJO9: 0.16892382 | AKC9: 0.035795273 | AKE9: 0.80782385 | AKZ9: 0.010508808 | ALI9: 0.022883176 | ALN9: 0.071248828 | AME9: 0.025080987 | AMH9: 0.057508408 | AMN9: 0.033782397 | AND9: 0.055565835 | ANL9: 0.010175793 | ANO9: 0.047667022 | ANZ9: 0.047756802 | AOJ9: 0.0053723791 | APD9: 0.020580143 | APF9: 0.039354852 | APW9: 0.1168617 | AQF9: 0.051488278 | AQM9: 0.46333503 | AQZ9: 0.015106416 | ASJ9: 0.064771746 | ATG9: 9.6751788
A10: 13B | E10: 0.015665661 | I10: 0.0099830118 | P10: 0.22151426 | Y10: 0.27607173 | AL10: 0.30546871 | BR10: 0.02805619 | EH10: 0.060946146 | EV10: 0.16880939 | FH10: 0.12889191 | FR10: 0.10182295 | GA10: 0.06122007 | GI10: 0.0696941 | HN10: 0.05436321 | HX10: 1.3195848 | JM10: 0.040881605 | JQ10: 0.27206378 | JV10: 0.66216777 | JZ10: 0.082343906 | LK10: 0.088534982 | LM10: 0.24982323 | MM10: 0.048725186 | MW10: 0.053877325 | NJ10: 0.18819931 | NN10: 0.064084228 | OL10: 0.057897189 | OR10: 0.021870115 | OV10: 0.1079179 | PB10: 0.026093054 | RY10: 1.0638298 | SD10: 0.063556104 | TP10: 0.019892459 | UI10: 0.041208405 | UZ10: 0.20827891 | XJ10: 0.094512142 | YP10: 0.04586481 | ABU10: 0.069113405 | ACF10: 0.090183781 | ADQ10: 0.051018853 | AFJ10: 0.021728647 | AGP10: 0.042346088 | AIS10: 0.041186955 | AJC10: 0.032388587 | AJO10: 0.051866543 | ALB10: 0.023045468 | ALN10: 0.055111951 | AND10: 0.047970378 | ANL10: 0.02191799 | ANO10: 0.06525095 | AOB10: 0.026532841 | APF10: 0.059639911 | APV10: 0.074925668 | AQE10: 0.045243195 | ARJ10: 0.051489406 | ASL10: 0.026299049 | ATG10: 7.220974
A11: 14A | D11: -0.013596517 | J11: 0.013498357 | Q11: 0.1070454 | AA11: 0.11741829 | BS11: 0.017101591 | CI11: 0.033653761 | CK11: 0.24614785 | DS11: 0.017222297 | DV11: 0.028071151 | EV11: 0.41497368 | FH11: 0.081716645 | FM11: 0.18953228 | FP11: 0.034512602 | GC11: 2.4517901 | HF11: 0.098317702 | JM11: 0.3641762 | JQ11: 0.24898709 | JY11: 0.048111558 | JZ11: 0.56648469 | KO11: 0.024058227 | LK11: 0.042682805 | MO11: 0.040024786 | NJ11: 0.10402381 | NP11: 0.031125448 | RY11: 0.70224719 | SD11: 0.025512607 | UU11: 0.040603953 | VC11: 0.90803577 | WK11: 0.01677543 | WR11: 0.058224676 | XP11: 0.082654951 | YL11: 0.021654045 | YQ11: 0.061201212 | ZH11: 0.23762873 | ZR11: 0.26884511 | ABQ11: 0.15741248 | ABU11: 0.024762396 | ACG11: 0.040381177 | ADN11: 0.061356735 | AGQ11: 0.023047153 | AIN11: 0.018000841 | AIT11: 0.093900469 | ALN11: 0.03812979 | AMN11: 0.023179143 | AND11: 0.029463504 | ANL11: 0.0023053249 | ANO11: 0.028064203 | ANU11: 0.019303298 | ANZ11: 0.036922086 | AOZ11: 0.010998667 | APD11: 0.01626251 | APF11: 0.02866909 | APK11: 0.023174382 | APW11: 0.037617682 | APZ11: 0.029732417 | AQD11: 0.039095906 | AQM11: 0.34855941 | AQZ11: 0.013010983 | ARU11: 0.015095371 | ASJ11: 0.060369988 | AST11: 0.04065729 | ATG11: 8.9899358
A12: 14B | E12: -0.017853876 | K12: 0.0096380753 | O12: 0.40361921 | JQ12: 0.11862631 | KA12: 0.23776353 | NJ12: 0.055159751 | RY12: 0.81699346 | VA12: 0.24111772 | ADR12: 0.075440832 | AJQ12: 0.048917193 | ALO12: 0.03848204 | AND12: 0.020727384 | ANL12: -0.00020517638 | ANP12: 0.049732845 | APD12: 0.027319356 | APF12: 0.044567624 | APO12: 0.0090949301 | APX12: 0.045572001 | AQA12: 0.042970123 | AQF12: 0.029796724 | AQM12: 0.1808733 | ATG12: 2.4783533
A13: 15A | E13: -0.039341966 | J13: 0.028075052 | R13: 0.10629319 | Y13: 0.61079294 | EV13: 0.11686607 | FH13: 0.090467889 | FM13: 0.13848129 | FQ13: 0.053381279 | JM13: 0.15477568 | JQ13: 0.34193646 | JY13: 0.044995349 | KA13: 0.17009112 | MO13: 0.053480606 | NA13: 0.11678276 | NJ13: 0.14213831 | NO13: 0.058611548 | OV13: 0.46337064 | RY13: 1.1876485 | VB13: 0.65591589 | YQ13: 0.034405138 | ZH13: 0.054747338 | ZR13: 0.054280834 | ABR13: 0.069624479 | ADQ13: 0.15469072 | AGQ13: 0.10676467 | AIS13: 0.10427474 | AJO13: 0.16873167 | ALN13: 0.07431072 | AMN13: 0.032419492 | AND13: 0.044030101 | ANL13: 0.025172623 | ANO13: 0.061645007 | ANU13: 0.037108306 | ANY13: 0.056419742 | APD13: 0.090031158 | APF13: 0.082106621 | APK13: 0.090626691 | APW13: 0.45851838 | AQM13: 0.94810127 | AQZ13: 0.076762228 | ARL13: 0.20878512 | ARV13: 0.085227362 | AST13: 0.052531549 | ATG13: 7.6660785
A14: 15B | F14: -0.014542189 | P14: 0.42228739 | AB14: 0.060135641 | AN14: 0.074612579 | EV14: 0.096311652 | FH14: 0.13332768 | GI14: 0.080796621 | JQ14: 0.26434266 | LK14: 0.067972964 | NJ14: 0.17837144 | NN14: 0.084050247 | RY14: 1.3157895 | SD14: 0.073986643 | TP14: 0.074995242 | UZ14: 0.43248983 | ABU14: 0.056535406 | ACG14: 0.084068866 | ADP14: 0.10680942 | AGP14: 0.14597978 | AJL14: 0.34307909 | AJN14: 0.33275169 | AKB14: 0.047545483 | ALH14: 0.06453133 | ALN14: 0.10751597 | AMD14: 0.045286916 | AMN14: 0.13849051 | AMV14: 0.05458968 | AND14: 0.052299333 | ANL14: 0.014375338 | ANO14: 0.068072661 | ANU14: 0.040751162 | APC14: 0.05104818 | APF14: 0.059527816 | APK14: 0.033558182 | APW14: 0.25847138 | AQM14: 1.5169244 | AQZ14: 0.037232681 | ARU14: 0.067943259 | AST14: 0.051271015 | ATG14: 7.1235875
A15: 16A | E15: 0.027291151 | J15: 0.010922311 | P15: 0.40198015 | AW15: 0.21579989 | AY15: 0.40164365 | BH15: 0.15671094 | BM15: 0.07036748 | BQ15: 0.12506834 | DJ15: 0.040230375 | EA15: 0.060883577 | EH15: 0.10338067 | EM15: 0.17210713 | ET15: 0.51413781 | FH15: 0.22171293 | FM15: 0.038662538 | GB15: 0.028900608 | GJ15: 0.070373694 | GT15: 0.041108479 | HF15: 0.089381975 | HN15: 0.073590497 | IF15: 0.15479098 | IZ15: 0.044260479 | JG15: 0.042733294 | JM15: 0.069483192 | JQ15: 0.32941061 | KA15: 0.62418416 | LI15: 0.030581315 | LK15: 0.039333045 | LV15: 0.058106794 | MC15: 0.037153876 | MR15: 0.031352499 | MX15: 0.090325966 | NG15: 0.07709239 | NJ15: 0.20873874 | NN15: 0.14390115 | OV15: 0.024401234 | QJ15: 0.080029964 | QP15: 0.04685326 | RK15: 0.050569785 | RO15: 0.055640893 | RX15: 0.084547187 | RY15: 1.2106538 | SE15: 0.082046789 | SG15: 0.037456405 | SP15: 0.050405067 | TJ15: 0.047277745 | TP15: 0.039560894 | TR15: 0.063686915 | TY15: 0.18170211 | UI15: 0.054581893 | UM15: 0.038007946 | UN15: 0.094855763 | UT15: 0.084032635 | UZ15: 0.34557734 | VY15: 0.038805039 | XF15: 0.02627972 | XO15: 0.047211594 | YP15: 0.10653803 | ZU15: 0.044909385 | ABR15: 0.017695991 | ABU15: 0.032872182 | ACF15: 0.11658728 | ADQ15: 0.049035946 | AFI15: 0.043420126 | AGP15: 0.073525401 | AHT15: 0.048927531 | AIR15: 0.032682785 | AJP15: 0.088661731 | ALN15: 0.06648486 | AMN15: 0.04540093 | AMV15: 0.040729482 | ANB15: 0.018138355 | AND15: 0.055738844 | ANL15: 0.016734473 | ANO15: 0.09142682 | ANY15: 0.079792178 | AOQ15: 0.067888947 | AOX15: 0.035931652 | APC15: 0.077487976 | APF15: 0.074675435 | APJ15: 0.060847469 | APW15: 0.22250821 | AQG15: 0.16656461 | AQM15: 0.46767311 | AQW15: 0.016344895 | ARC15: 0.082504511 | ARH15: 0.26790917 | ASK15: 0.14288582 | ASS15: 0.048055817 | ATG15: 10.430467
A16: 16B | D16: -0.011001858 | Q16: 0.068540762 | Z16: 0.13913842 | EH16: 0.12925412 | EV16: 0.18719765 | FH16: 0.095650983 | FM16: 0.25005713 | FP16: 0.051317258 | GD16: 0.051237827 | GI16: 0.073461552 | HF16: 0.39463777 | JM16: 0.080601202 | JQ16: 0.2796236 | JX16: 0.038597097 | KA16: 0.34691798 | LK16: 0.036948176 | MO16: 0.057634233 | MX16: 0.20632506 | NJ16: 0.22104339 | NO16: 0.053103956 | OR16: 0.03921168 | OV16: 0.1075184 | RP16: 0.072893644 | RV16: 0.057515484 | RY16: 0.95419847 | SD16: 0.052919147 | TP16: 0.034761686 | TU16: 0.032147316 | UT16: 0.10438865 | VB16: 0.5211139 | WR16: 0.064526693 | XH16: 0.033132369 | XP16: 0.091672223 | YQ16: 0.089508632 | ZH16: 0.26953396 | ZR16: 0.31516818 | AAT16: 0.032394643 | AAZ16: 0.16443559 | ABR16: 0.059506402 | ABU16: 0.032395549 | ACG16: 0.070601337 | ADP16: 0.12085716 | AEP16: 0.056369564 | AGP16: 0.051214132 | AIN16: 0.030682023 | AIS16: 0.059550442 | AJO16: 0.15390471 | AKV16: 0.027530222 | ALN16: 0.063033752 | AMD16: 0.024831698 | AMI16: 0.022111346 | AMN16: 0.056301005 | AMV16: 0.059930822 | AMX16: 0.009777468 | ANB16: 0.013314565 | AND16: 0.030778368 | ANO16: 0.02870563 | ANU16: 0.042735214 | APD16: 0.06612147 | APE16: 0.039569794 | APK16: 0.043052637 | APS16: 0.016919425 | AQM16: 0.16048777 | AQQ16: 0.11167959 | ARU16: 0.045569208 | ASS16: 0.042624757 | ATG16: 7.327483
A17: 17A | D17: 0.0035084642 | Q17: 0.10134227 | Z17: 0.16410331 | EV17: 0.08053297 | FH17: 0.04488853 | HF17: 0.12855924 | JM17: 0.070110207 | JQ17: 0.19642127 | JZ17: 2.3078895 | LK17: 0.034483997 | NJ17: 0.055253294 | OW17: 0.023626839 | RY17: 0.72254335 | VB17: 0.63288368 | ABR17: 0.07581242 | ADS17: 0.036669077 | AIU17: 0.037905382 | AJR17: 0.011698786 | ALN17: 0.03710954 | AND17: 0.024432558 | ANT17: 0.26692474 | APF17: 0.054513375 | APK17: 0.030009762 | APX17: 0.041807316 | AQB17: 0.021064891 | AQM17: 0.17995607 | AQQ17: 0.095429811 | ARI17: 0.17095906 | ARU17: 0.045826719 | ASS17: 0.059208787 | ATG17: 5.7554752
A18: 17B | E18: 0.060453242 | G18: 0.015944796 | I18: 0.013791989 | P18: 0.065331384 | Y18: 0.10424041 | AE18: 0.047547893 | AG18: 0.025699889 | AJ18: 0.078438808 | AR18: 0.02391797 | AW18: 0.16646363 | AX18: 0.29627703 | BE18: 0.093623084 | BJ18: 0.051242373 | BM18: 0.048261085 | BP18: 0.072344624 | CF18: 0.018692578 | CJ18: 0.082386806 | CL18: 0.014703096 | CN18: 0.017526332 | CQ18: 0.018113585 | CX18: 0.044094228 | DA18: 0.023813606 | DC18: 0.055562785 | DE18: 0.098865537 | DN18: 0.033338154 | DQ18: 0.038107445 | DT18: 0.050638584 | DZ18: 0.051363833 | ED18: 0.039491533 | EL18: 0.12224549 | EN18: 0.34163917 | ES18: 0.34469677 | EV18: 0.2088464 | FB18: 0.17174422 | FE18: 0.075271982 | FF18: 0.21174833 | FH18: 0.4501536 | FM18: 0.11712342 | FO18: 0.11230235 | FV18: 0.087344664 | FX18: 0.069385196 | GA18: 0.45400223 | GC18: 0.28403303 | GF18: 0.18603395 | GK18: 0.11327799 | GU18: 0.082420575 | GW18: 0.072972705 | HB18: 0.10948504 | HF18: 0.51827507 | HO18: 0.1718617 | HP18: 0.24481453 | HS18: 0.16941777 | HW18: 0.42553717 | IH18: 1.0905145 | IM18: 0.59107184 | IQ18: 0.63933631 | IW18: 0.78760617 | JC18: 0.43934518 | JL18: 0.54546138 | JM18: 0.53282815 | JO18: 0.27542934 | JQ18: 1.5809446 | JT18: 0.30907923 | JX18: 0.43197017 | JZ18: 0.54630795 | KC18: 0.28752998 | KH18: 0.56266808 | KK18: 0.21671595 | KL18: 0.21489959 | KQ18: 0.37555146 | KT18: 0.11165684 | LC18: 0.14331142 | LE18: 0.12395991 | LF18: 0.11392214 | LK18: 0.49230673 | LO18: 0.069229975 | LQ18: 0.05625706 | LS18: 0.16989968 | MC18: 0.23931518 | MH18: 0.16562163 | MJ18: 0.17621257 | MO18: 0.14227647 | MQ18: 0.1401515 | MV18: 0.23471064 | NE18: 0.35546993 | NJ18: 0.78913302 | NM18: 0.2022342 | NX18: 0.18342452 | OA18: 0.1782063 | OG18: 0.12491389 | OS18: 0.086653962 | OT18: 0.099109476 | OZ18: 0.1178804 | PF18: 0.1935159 | PO18: 0.7607423 | PQ18: 0.13462335 | PW18: 0.33606565 | QF18: 0.096312726 | QI18: 0.45009356 | QM18: 0.1059838 | QO18: 0.41189198 | QU18: 0.19338657 | RA18: 0.19838865 | RD18: 0.33894811 | RN18: 0.33463953 | RO18: 0.30288609 | RR18: 0.17655423 | RS18: 0.44624092 | RY18: 0.78740157 | RZ18: 0.46374424 | SC18: 3.4057276 | SG18: 4.9612825 | SH18: 1.0011646 | SO18: 5.9612916 | SU18: 0.34266283 | SZ18: 0.40200901 | TD18: 0.57537169 | TI18: 0.79210014 | TO18: 0.59620008 | TP18: 1.1830242 | TS18: 0.40437199 | TX18: 1.2795852 | UA18: 0.16223274 | UD18: 0.35065232 | UF18: 0.16113689 | UI18: 0.43454802 | UL18: 0.47831143 | UN18: 1.432347 | UP18: 1.8863355 | US18: 0.93334762 | UY18: 0.79162555 | VF18: 1.610416 | VJ18: 0.23340905 | VN18: 0.78474903 | VU18: 0.76844762 | WC18: 0.76116241 | WH18: 1.1439899 | WK18: 0.40771719 | WN18: 0.44485455 | WQ18: 0.17793907 | WT18: 0.49249995 | WW18: 0.87263204 | XA18: 0.89408786 | XF18: 0.6309719 | XL18: 0.18059097 | XQ18: 0.45031559 | XU18: 0.29381571 | XX18: 0.32310739 | YF18: 0.55787981 | YM18: 0.32322658 | YO18: 0.43214251 | YU18: 0.58285957 | YZ18: 0.22861584 | ZF18: 0.29785466 | ZJ18: 0.20910746 | ZN18: 0.24397906 | ZP18: 0.32142797 | ZZ18: 0.73253508 | AAC18: 0.19972056 | AAE18: 0.67649838 | AAH18: 0.1834617 | AAJ18: 0.82923129 | AAN18: 0.23036074 | AAO18: 0.23576597 | AAQ18: 0.22802742 | AAS18: 0.45279942 | AAX18: 0.14653142 | ABB18: 0.2750914 | ABF18: 0.18262974 | ABK18: 0.37134387 | ABU18: 0.80706098 | ABZ18: 0.14742612 | ACB18: 0.39685209 | ACE18: 0.37973198 | ACN18: 0.55271379 | ACT18: 0.24900414 | ACX18: 0.52468211 | ACY18: 0.55355071 | ADF18: 0.48080132 | ADG18: 0.33730539 | ADT18: 0.913525 | ADV18: 0.54456563 | AEC18: 0.87088156 | AEF18: 0.35321221 | AEH18: 0.57898632 | AEL18: 0.69359264 | AEP18: 0.45307047 | AEU18: 0.42646249 | AEW18: 0.51147272 | AEZ18: 0.69601878 | AFB18: 0.51007225 | AFF18: 0.32632954 | AFI18: 0.88098961 | AFL18: 0.83908999 | AFS18: 0.52352492 | AFT18: 0.47061788 | AFW18: 0.37027044 | AGA18: 0.21807304 | AGD18: 0.49093496 | AGG18: 0.66493563 | AGL18: 0.72864915 | AGO18: 0.55399703 | AGR18: 0.32263627 | AGU18: 0.2211466 | AGW18: 0.22408492 | AGZ18: 0.40324556 | AHC18: 0.34214191 | AHF18: 0.23946024 | AHG18: 0.42229914 | AHJ18: 0.34234592 | AHL18: 0.31091115 | AHO18: 0.18419422 | AHQ18: 0.31961484 | AHV18: 0.27854969 | AHZ18: 0.29985264 | AIE18: 0.21012567 | AIG18: 0.22024584 | AIJ18: 0.042711918 | AIK18: 0.20181235 | AIO18: 0.54987628 | AIX18: 0.14548605 | AIY18: 0.1346448 | AJE18: 0.22537489 | AJF18: 0.4644639 | AJJ18: 0.26069601 | AJM18: 0.22408626 | AJX18: 0.045638732 | AJZ18: 0.04861794 | AKC18: 0.15007826 | AKF18: 0.052207598 | AKI18: 0.057274075 | AKL18: 0.015960028 | AKS18: 0.025235045 | AKX18: 0.013875598 | ALB18: 0.00924073 | ALC18: 0.012497206 | ALG18: 0.0245826 | ALK18: 0.0083850204 | ALN18: 0.029186072 | ALS18: 0.0075566941 | ALU18: 0.012697243 | ALY18: 0.0082739164 | AMD18: 0.015810477 | AMF18: 0.016157536 | AMN18: 0.033403691 | AMP18: 0.0063133115 | AMS18: 0.017048327 | AMU18: 0.025443436 | ANA18: 0.012698943 | AND18: 0.027325084 | ANH18: 0.034895716 | ANL18: 0.0066304766 | ANO18: 0.024439789 | ANU18: 0.01289968 | ANY18: 0.025408536 | AOQ18: 0.012288193 | AOZ18: 0.0040223116 | APC18: 0.0080893012 | APE18: 0.011931157 | APK18: 0.0098472712 | APQ18: 0.0086261283 | APR18: 0.009983204 | APV18: 0.012190699 | APZ18: 0.017498689 | AQM18: 0.16706476 | AQZ18: 0.0045503274 | ARK18: 0.020744542 | ASK18: 0.03795855 | ASS18: 0.01129139 | ATG18: 97.270848
